2024-06-07 21:54:45,721 - WARNING - Session data corrupted
2024-06-07 21:54:45,775 - WARNING - Session data corrupted
2024-06-07 21:54:49,424 - WARNING - Session data corrupted
2024-06-07 21:54:50,065 - WARNING - Session data corrupted
2024-06-07 21:54:50,082 - WARNING - Session data corrupted
2024-06-07 21:55:14,202 - WARNING - Session data corrupted
2024-06-07 21:56:25,486 - WARNING - Session data corrupted
2024-06-08 09:59:55,621 - WARNING - Session data corrupted
2024-06-08 09:59:55,758 - WARNING - Session data corrupted
2024-06-08 09:59:56,164 - WARNING - Not Found: /favicon.ico
2024-06-08 10:00:29,175 - WARNING - Session data corrupted
2024-06-08 10:15:38,921 - WARNING - Method Not Allowed (GET): /accounts/logout/
2024-06-08 10:15:38,925 - WARNING - Method Not Allowed: /accounts/logout/
2024-06-08 10:15:41,642 - WARNING - Method Not Allowed (GET): /accounts/logout/
2024-06-08 10:15:41,645 - WARNING - Method Not Allowed: /accounts/logout/
2024-06-08 10:15:42,577 - WARNING - Method Not Allowed (GET): /accounts/logout/
2024-06-08 10:15:42,577 - WARNING - Method Not Allowed: /accounts/logout/
2024-06-08 10:15:43,059 - WARNING - Method Not Allowed (GET): /accounts/logout/
2024-06-08 10:15:43,059 - WARNING - Method Not Allowed: /accounts/logout/
2024-06-08 10:15:43,244 - WARNING - Method Not Allowed (GET): /accounts/logout/
2024-06-08 10:15:43,244 - WARNING - Method Not Allowed: /accounts/logout/
2024-06-08 10:15:43,551 - WARNING - Method Not Allowed (GET): /accounts/logout/
2024-06-08 10:15:43,553 - WARNING - Method Not Allowed: /accounts/logout/
2024-06-08 10:15:50,063 - WARNING - Method Not Allowed (GET): /accounts/logout/
2024-06-08 10:15:50,063 - WARNING - Method Not Allowed: /accounts/logout/
2024-06-08 10:31:31,105 - INFO - C:\Users\ASWANI\new prj-Trouble Tracker\trouble_tracker\trouble_app\models.py changed, reloading.
2024-06-08 10:32:39,936 - INFO - C:\Users\ASWANI\new prj-Trouble Tracker\trouble_tracker\trouble_app\views.py changed, reloading.
2024-06-08 10:34:23,684 - INFO - C:\Users\ASWANI\new prj-Trouble Tracker\trouble_tracker\trouble_app\views.py changed, reloading.
2024-06-08 10:35:38,357 - INFO - C:\Users\ASWANI\new prj-Trouble Tracker\trouble_tracker\trouble_app\views.py changed, reloading.
2024-06-08 10:36:33,169 - INFO - C:\Users\ASWANI\new prj-Trouble Tracker\trouble_tracker\trouble_app\admin.py changed, reloading.
2024-06-08 10:36:40,760 - INFO - C:\Users\ASWANI\new prj-Trouble Tracker\trouble_tracker\trouble_app\admin.py changed, reloading.
2024-06-08 10:41:35,982 - INFO - C:\Users\ASWANI\new prj-Trouble Tracker\trouble_tracker\trouble_tracker\urls.py changed, reloading.
2024-06-08 10:41:40,298 - INFO - C:\Users\ASWANI\new prj-Trouble Tracker\trouble_tracker\trouble_tracker\urls.py changed, reloading.
2024-06-08 10:41:47,864 - INFO - C:\Users\ASWANI\new prj-Trouble Tracker\trouble_tracker\trouble_tracker\urls.py changed, reloading.
2024-06-08 10:41:54,213 - INFO - C:\Users\ASWANI\new prj-Trouble Tracker\trouble_tracker\trouble_tracker\urls.py changed, reloading.
2024-06-08 10:42:02,760 - INFO - C:\Users\ASWANI\new prj-Trouble Tracker\trouble_tracker\trouble_tracker\urls.py changed, reloading.
2024-06-08 10:42:06,056 - INFO - C:\Users\ASWANI\new prj-Trouble Tracker\trouble_tracker\trouble_tracker\urls.py changed, reloading.
2024-06-08 10:42:10,290 - INFO - C:\Users\ASWANI\new prj-Trouble Tracker\trouble_tracker\trouble_tracker\urls.py changed, reloading.
2024-06-08 10:42:14,767 - INFO - C:\Users\ASWANI\new prj-Trouble Tracker\trouble_tracker\trouble_tracker\urls.py changed, reloading.
2024-06-08 10:42:17,069 - INFO - C:\Users\ASWANI\new prj-Trouble Tracker\trouble_tracker\trouble_tracker\urls.py changed, reloading.
2024-06-08 10:44:36,904 - INFO - C:\Users\ASWANI\new prj-Trouble Tracker\trouble_tracker\trouble_app\urls.py changed, reloading.
2024-06-08 10:44:39,990 - INFO - C:\Users\ASWANI\new prj-Trouble Tracker\trouble_tracker\trouble_app\urls.py changed, reloading.
2024-06-08 10:48:38,485 - INFO - C:\Users\ASWANI\new prj-Trouble Tracker\trouble_tracker\trouble_app\views.py changed, reloading.
2024-06-08 12:32:21,527 - WARNING - Not Found: /favicon.ico
2024-06-08 12:47:49,813 - INFO - C:\Users\ASWANI\new prj-Trouble Tracker\trouble_tracker\trouble_app\models.py changed, reloading.
2024-06-08 12:49:36,780 - INFO - C:\Users\ASWANI\new prj-Trouble Tracker\trouble_tracker\trouble_app\views.py changed, reloading.
2024-06-08 12:54:40,136 - INFO - C:\Users\ASWANI\new prj-Trouble Tracker\trouble_tracker\trouble_app\forms.py changed, reloading.
2024-06-08 12:54:43,593 - INFO - C:\Users\ASWANI\new prj-Trouble Tracker\trouble_tracker\trouble_app\forms.py changed, reloading.
2024-06-08 12:55:00,621 - INFO - C:\Users\ASWANI\new prj-Trouble Tracker\trouble_tracker\trouble_app\forms.py changed, reloading.
2024-06-08 12:55:53,979 - INFO - C:\Users\ASWANI\new prj-Trouble Tracker\trouble_tracker\trouble_app\forms.py changed, reloading.
2024-06-08 12:55:58,340 - INFO - C:\Users\ASWANI\new prj-Trouble Tracker\trouble_tracker\trouble_app\forms.py changed, reloading.
2024-06-08 12:57:01,373 - INFO - C:\Users\ASWANI\new prj-Trouble Tracker\trouble_tracker\trouble_app\admin.py changed, reloading.
2024-06-08 12:57:51,292 - INFO - C:\Users\ASWANI\new prj-Trouble Tracker\trouble_tracker\trouble_app\admin.py changed, reloading.
2024-06-08 13:06:43,474 - INFO - C:\Users\ASWANI\new prj-Trouble Tracker\trouble_tracker\trouble_tracker\settings.py changed, reloading.
2024-06-08 13:06:45,774 - INFO - C:\Users\ASWANI\new prj-Trouble Tracker\trouble_tracker\trouble_tracker\settings.py changed, reloading.
2024-06-08 13:10:08,683 - INFO - C:\Users\ASWANI\new prj-Trouble Tracker\trouble_tracker\trouble_tracker\settings.py changed, reloading.
2024-06-08 14:24:16,403 - WARNING - Not Found: /favicon.ico
2024-06-08 14:24:38,509 - ERROR - Internal Server Error: /
Traceback (most recent call last):
  File "C:\Users\ASWANI\AppData\Local\Programs\Python\Python312\Lib\site-packages\django\template\base.py", line 502, in parse
    compile_func = self.tags[command]
                   ~~~~~~~~~^^^^^^^^^
KeyError: 'issues'

During handling of the above exception, another exception occurred:

Traceback (most recent call last):
  File "C:\Users\ASWANI\AppData\Local\Programs\Python\Python312\Lib\site-packages\django\core\handlers\exception.py", line 55, in inner
    response = get_response(request)
               ^^^^^^^^^^^^^^^^^^^^^
  File "C:\Users\ASWANI\AppData\Local\Programs\Python\Python312\Lib\site-packages\django\core\handlers\base.py", line 197, in _get_response
    response = wrapped_callback(request, *callback_args, **callback_kwargs)
               ^^^^^^^^^^^^^^^^^^^^^^^^^^^^^^^^^^^^^^^^^^^^^^^^^^^^^^^^^^^^
  File "C:\Users\ASWANI\AppData\Local\Programs\Python\Python312\Lib\site-packages\django\contrib\auth\decorators.py", line 23, in _wrapper_view
    return view_func(request, *args, **kwargs)
           ^^^^^^^^^^^^^^^^^^^^^^^^^^^^^^^^^^^
  File "C:\Users\ASWANI\new prj-Trouble Tracker\trouble_tracker\trouble_app\views.py", line 48, in index
    return render(request, 'index.html', {'issues': issues})
           ^^^^^^^^^^^^^^^^^^^^^^^^^^^^^^^^^^^^^^^^^^^^^^^^^
  File "C:\Users\ASWANI\AppData\Local\Programs\Python\Python312\Lib\site-packages\django\shortcuts.py", line 24, in render
    content = loader.render_to_string(template_name, context, request, using=using)
              ^^^^^^^^^^^^^^^^^^^^^^^^^^^^^^^^^^^^^^^^^^^^^^^^^^^^^^^^^^^^^^^^^^^^^
  File "C:\Users\ASWANI\AppData\Local\Programs\Python\Python312\Lib\site-packages\django\template\loader.py", line 61, in render_to_string
    template = get_template(template_name, using=using)
               ^^^^^^^^^^^^^^^^^^^^^^^^^^^^^^^^^^^^^^^^
  File "C:\Users\ASWANI\AppData\Local\Programs\Python\Python312\Lib\site-packages\django\template\loader.py", line 15, in get_template
    return engine.get_template(template_name)
           ^^^^^^^^^^^^^^^^^^^^^^^^^^^^^^^^^^
  File "C:\Users\ASWANI\AppData\Local\Programs\Python\Python312\Lib\site-packages\django\template\backends\django.py", line 33, in get_template
    return Template(self.engine.get_template(template_name), self)
                    ^^^^^^^^^^^^^^^^^^^^^^^^^^^^^^^^^^^^^^^
  File "C:\Users\ASWANI\AppData\Local\Programs\Python\Python312\Lib\site-packages\django\template\engine.py", line 175, in get_template
    template, origin = self.find_template(template_name)
                       ^^^^^^^^^^^^^^^^^^^^^^^^^^^^^^^^^
  File "C:\Users\ASWANI\AppData\Local\Programs\Python\Python312\Lib\site-packages\django\template\engine.py", line 157, in find_template
    template = loader.get_template(name, skip=skip)
               ^^^^^^^^^^^^^^^^^^^^^^^^^^^^^^^^^^^^
  File "C:\Users\ASWANI\AppData\Local\Programs\Python\Python312\Lib\site-packages\django\template\loaders\cached.py", line 57, in get_template
    template = super().get_template(template_name, skip)
               ^^^^^^^^^^^^^^^^^^^^^^^^^^^^^^^^^^^^^^^^^
  File "C:\Users\ASWANI\AppData\Local\Programs\Python\Python312\Lib\site-packages\django\template\loaders\base.py", line 28, in get_template
    return Template(
           ^^^^^^^^^
  File "C:\Users\ASWANI\AppData\Local\Programs\Python\Python312\Lib\site-packages\django\template\base.py", line 154, in __init__
    self.nodelist = self.compile_nodelist()
                    ^^^^^^^^^^^^^^^^^^^^^^^
  File "C:\Users\ASWANI\AppData\Local\Programs\Python\Python312\Lib\site-packages\django\template\base.py", line 196, in compile_nodelist
    return parser.parse()
           ^^^^^^^^^^^^^^
  File "C:\Users\ASWANI\AppData\Local\Programs\Python\Python312\Lib\site-packages\django\template\base.py", line 504, in parse
    self.invalid_block_tag(token, command, parse_until)
  File "C:\Users\ASWANI\AppData\Local\Programs\Python\Python312\Lib\site-packages\django\template\base.py", line 565, in invalid_block_tag
    raise self.error(
django.template.exceptions.TemplateSyntaxError: Invalid block tag on line 2: 'issues'. Did you forget to register or load this tag?
2024-06-08 14:24:43,798 - ERROR - Internal Server Error: /accounts/login/
Traceback (most recent call last):
  File "C:\Users\ASWANI\AppData\Local\Programs\Python\Python312\Lib\site-packages\django\core\handlers\exception.py", line 55, in inner
    response = get_response(request)
               ^^^^^^^^^^^^^^^^^^^^^
  File "C:\Users\ASWANI\AppData\Local\Programs\Python\Python312\Lib\site-packages\django\core\handlers\base.py", line 220, in _get_response
    response = response.render()
               ^^^^^^^^^^^^^^^^^
  File "C:\Users\ASWANI\AppData\Local\Programs\Python\Python312\Lib\site-packages\django\template\response.py", line 114, in render
    self.content = self.rendered_content
                   ^^^^^^^^^^^^^^^^^^^^^
  File "C:\Users\ASWANI\AppData\Local\Programs\Python\Python312\Lib\site-packages\django\template\response.py", line 92, in rendered_content
    return template.render(context, self._request)
           ^^^^^^^^^^^^^^^^^^^^^^^^^^^^^^^^^^^^^^^
  File "C:\Users\ASWANI\AppData\Local\Programs\Python\Python312\Lib\site-packages\django\template\backends\django.py", line 61, in render
    return self.template.render(context)
           ^^^^^^^^^^^^^^^^^^^^^^^^^^^^^
  File "C:\Users\ASWANI\AppData\Local\Programs\Python\Python312\Lib\site-packages\django\template\base.py", line 171, in render
    return self._render(context)
           ^^^^^^^^^^^^^^^^^^^^^
  File "C:\Users\ASWANI\AppData\Local\Programs\Python\Python312\Lib\site-packages\django\template\base.py", line 163, in _render
    return self.nodelist.render(context)
           ^^^^^^^^^^^^^^^^^^^^^^^^^^^^^
  File "C:\Users\ASWANI\AppData\Local\Programs\Python\Python312\Lib\site-packages\django\template\base.py", line 1000, in render
    return SafeString("".join([node.render_annotated(context) for node in self]))
                               ^^^^^^^^^^^^^^^^^^^^^^^^^^^^^^
  File "C:\Users\ASWANI\AppData\Local\Programs\Python\Python312\Lib\site-packages\django\template\base.py", line 961, in render_annotated
    return self.render(context)
           ^^^^^^^^^^^^^^^^^^^^
  File "C:\Users\ASWANI\AppData\Local\Programs\Python\Python312\Lib\site-packages\django\template\loader_tags.py", line 159, in render
    return compiled_parent._render(context)
           ^^^^^^^^^^^^^^^^^^^^^^^^^^^^^^^^
  File "C:\Users\ASWANI\AppData\Local\Programs\Python\Python312\Lib\site-packages\django\template\base.py", line 163, in _render
    return self.nodelist.render(context)
           ^^^^^^^^^^^^^^^^^^^^^^^^^^^^^
  File "C:\Users\ASWANI\AppData\Local\Programs\Python\Python312\Lib\site-packages\django\template\base.py", line 1000, in render
    return SafeString("".join([node.render_annotated(context) for node in self]))
                               ^^^^^^^^^^^^^^^^^^^^^^^^^^^^^^
  File "C:\Users\ASWANI\AppData\Local\Programs\Python\Python312\Lib\site-packages\django\template\base.py", line 961, in render_annotated
    return self.render(context)
           ^^^^^^^^^^^^^^^^^^^^
  File "C:\Users\ASWANI\AppData\Local\Programs\Python\Python312\Lib\site-packages\django\template\defaulttags.py", line 325, in render
    return nodelist.render(context)
           ^^^^^^^^^^^^^^^^^^^^^^^^
  File "C:\Users\ASWANI\AppData\Local\Programs\Python\Python312\Lib\site-packages\django\template\base.py", line 1000, in render
    return SafeString("".join([node.render_annotated(context) for node in self]))
                               ^^^^^^^^^^^^^^^^^^^^^^^^^^^^^^
  File "C:\Users\ASWANI\AppData\Local\Programs\Python\Python312\Lib\site-packages\django\template\base.py", line 961, in render_annotated
    return self.render(context)
           ^^^^^^^^^^^^^^^^^^^^
  File "C:\Users\ASWANI\AppData\Local\Programs\Python\Python312\Lib\site-packages\django\template\defaulttags.py", line 478, in render
    url = reverse(view_name, args=args, kwargs=kwargs, current_app=current_app)
          ^^^^^^^^^^^^^^^^^^^^^^^^^^^^^^^^^^^^^^^^^^^^^^^^^^^^^^^^^^^^^^^^^^^^^
  File "C:\Users\ASWANI\AppData\Local\Programs\Python\Python312\Lib\site-packages\django\urls\base.py", line 88, in reverse
    return resolver._reverse_with_prefix(view, prefix, *args, **kwargs)
           ^^^^^^^^^^^^^^^^^^^^^^^^^^^^^^^^^^^^^^^^^^^^^^^^^^^^^^^^^^^^
  File "C:\Users\ASWANI\AppData\Local\Programs\Python\Python312\Lib\site-packages\django\urls\resolvers.py", line 848, in _reverse_with_prefix
    raise NoReverseMatch(msg)
django.urls.exceptions.NoReverseMatch: Reverse for 'dashboard' not found. 'dashboard' is not a valid view function or pattern name.
2024-06-11 12:25:33,841 - WARNING - Not Found: /favicon.ico
2024-06-11 12:34:22,336 - INFO - C:\Users\ASWANI\new prj-Trouble Tracker\trouble_tracker\trouble_app\views.py changed, reloading.
2024-06-11 12:34:29,519 - INFO - C:\Users\ASWANI\new prj-Trouble Tracker\trouble_tracker\trouble_app\views.py changed, reloading.
2024-06-11 12:35:43,241 - INFO - C:\Users\ASWANI\new prj-Trouble Tracker\trouble_tracker\trouble_app\forms.py changed, reloading.
2024-06-11 13:02:52,497 - INFO - C:\Users\ASWANI\new prj-Trouble Tracker\trouble_tracker\trouble_app\admin.py changed, reloading.
2024-06-11 13:02:55,978 - INFO - C:\Users\ASWANI\new prj-Trouble Tracker\trouble_tracker\trouble_app\admin.py changed, reloading.
2024-06-11 13:03:47,958 - INFO - C:\Users\ASWANI\new prj-Trouble Tracker\trouble_tracker\trouble_app\admin.py changed, reloading.
2024-06-11 13:04:31,489 - INFO - C:\Users\ASWANI\new prj-Trouble Tracker\trouble_tracker\trouble_app\admin.py changed, reloading.
2024-06-11 13:15:30,765 - ERROR - Internal Server Error: /
Traceback (most recent call last):
  File "C:\Users\ASWANI\AppData\Local\Programs\Python\Python312\Lib\site-packages\django\core\handlers\exception.py", line 55, in inner
    response = get_response(request)
               ^^^^^^^^^^^^^^^^^^^^^
  File "C:\Users\ASWANI\AppData\Local\Programs\Python\Python312\Lib\site-packages\django\core\handlers\base.py", line 197, in _get_response
    response = wrapped_callback(request, *callback_args, **callback_kwargs)
               ^^^^^^^^^^^^^^^^^^^^^^^^^^^^^^^^^^^^^^^^^^^^^^^^^^^^^^^^^^^^
  File "C:\Users\ASWANI\AppData\Local\Programs\Python\Python312\Lib\site-packages\django\contrib\auth\decorators.py", line 23, in _wrapper_view
    return view_func(request, *args, **kwargs)
           ^^^^^^^^^^^^^^^^^^^^^^^^^^^^^^^^^^^
  File "C:\Users\ASWANI\new prj-Trouble Tracker\trouble_tracker\trouble_app\views.py", line 48, in index
    return render(request, 'index.html', {'issues': issues})
           ^^^^^^^^^^^^^^^^^^^^^^^^^^^^^^^^^^^^^^^^^^^^^^^^^
  File "C:\Users\ASWANI\AppData\Local\Programs\Python\Python312\Lib\site-packages\django\shortcuts.py", line 24, in render
    content = loader.render_to_string(template_name, context, request, using=using)
              ^^^^^^^^^^^^^^^^^^^^^^^^^^^^^^^^^^^^^^^^^^^^^^^^^^^^^^^^^^^^^^^^^^^^^
  File "C:\Users\ASWANI\AppData\Local\Programs\Python\Python312\Lib\site-packages\django\template\loader.py", line 62, in render_to_string
    return template.render(context, request)
           ^^^^^^^^^^^^^^^^^^^^^^^^^^^^^^^^^
  File "C:\Users\ASWANI\AppData\Local\Programs\Python\Python312\Lib\site-packages\django\template\backends\django.py", line 61, in render
    return self.template.render(context)
           ^^^^^^^^^^^^^^^^^^^^^^^^^^^^^
  File "C:\Users\ASWANI\AppData\Local\Programs\Python\Python312\Lib\site-packages\django\template\base.py", line 171, in render
    return self._render(context)
           ^^^^^^^^^^^^^^^^^^^^^
  File "C:\Users\ASWANI\AppData\Local\Programs\Python\Python312\Lib\site-packages\django\template\base.py", line 163, in _render
    return self.nodelist.render(context)
           ^^^^^^^^^^^^^^^^^^^^^^^^^^^^^
  File "C:\Users\ASWANI\AppData\Local\Programs\Python\Python312\Lib\site-packages\django\template\base.py", line 1000, in render
    return SafeString("".join([node.render_annotated(context) for node in self]))
                               ^^^^^^^^^^^^^^^^^^^^^^^^^^^^^^
  File "C:\Users\ASWANI\AppData\Local\Programs\Python\Python312\Lib\site-packages\django\template\base.py", line 961, in render_annotated
    return self.render(context)
           ^^^^^^^^^^^^^^^^^^^^
  File "C:\Users\ASWANI\AppData\Local\Programs\Python\Python312\Lib\site-packages\django\template\defaulttags.py", line 325, in render
    return nodelist.render(context)
           ^^^^^^^^^^^^^^^^^^^^^^^^
  File "C:\Users\ASWANI\AppData\Local\Programs\Python\Python312\Lib\site-packages\django\template\base.py", line 1000, in render
    return SafeString("".join([node.render_annotated(context) for node in self]))
                               ^^^^^^^^^^^^^^^^^^^^^^^^^^^^^^
  File "C:\Users\ASWANI\AppData\Local\Programs\Python\Python312\Lib\site-packages\django\template\base.py", line 961, in render_annotated
    return self.render(context)
           ^^^^^^^^^^^^^^^^^^^^
  File "C:\Users\ASWANI\AppData\Local\Programs\Python\Python312\Lib\site-packages\django\template\defaulttags.py", line 478, in render
    url = reverse(view_name, args=args, kwargs=kwargs, current_app=current_app)
          ^^^^^^^^^^^^^^^^^^^^^^^^^^^^^^^^^^^^^^^^^^^^^^^^^^^^^^^^^^^^^^^^^^^^^
  File "C:\Users\ASWANI\AppData\Local\Programs\Python\Python312\Lib\site-packages\django\urls\base.py", line 88, in reverse
    return resolver._reverse_with_prefix(view, prefix, *args, **kwargs)
           ^^^^^^^^^^^^^^^^^^^^^^^^^^^^^^^^^^^^^^^^^^^^^^^^^^^^^^^^^^^^
  File "C:\Users\ASWANI\AppData\Local\Programs\Python\Python312\Lib\site-packages\django\urls\resolvers.py", line 848, in _reverse_with_prefix
    raise NoReverseMatch(msg)
django.urls.exceptions.NoReverseMatch: Reverse for 'create_issue' not found. 'create_issue' is not a valid view function or pattern name.
2024-06-11 13:15:44,773 - ERROR - Internal Server Error: /issues/
Traceback (most recent call last):
  File "C:\Users\ASWANI\AppData\Local\Programs\Python\Python312\Lib\site-packages\django\template\base.py", line 502, in parse
    compile_func = self.tags[command]
                   ~~~~~~~~~^^^^^^^^^
KeyError: 'endfor'

During handling of the above exception, another exception occurred:

Traceback (most recent call last):
  File "C:\Users\ASWANI\AppData\Local\Programs\Python\Python312\Lib\site-packages\django\core\handlers\exception.py", line 55, in inner
    response = get_response(request)
               ^^^^^^^^^^^^^^^^^^^^^
  File "C:\Users\ASWANI\AppData\Local\Programs\Python\Python312\Lib\site-packages\django\core\handlers\base.py", line 197, in _get_response
    response = wrapped_callback(request, *callback_args, **callback_kwargs)
               ^^^^^^^^^^^^^^^^^^^^^^^^^^^^^^^^^^^^^^^^^^^^^^^^^^^^^^^^^^^^
  File "C:\Users\ASWANI\AppData\Local\Programs\Python\Python312\Lib\site-packages\django\contrib\auth\decorators.py", line 23, in _wrapper_view
    return view_func(request, *args, **kwargs)
           ^^^^^^^^^^^^^^^^^^^^^^^^^^^^^^^^^^^
  File "C:\Users\ASWANI\new prj-Trouble Tracker\trouble_tracker\trouble_app\views.py", line 81, in issue_list
    return render(request, 'issue_list.html', {'issues': issues})
           ^^^^^^^^^^^^^^^^^^^^^^^^^^^^^^^^^^^^^^^^^^^^^^^^^^^^^^
  File "C:\Users\ASWANI\AppData\Local\Programs\Python\Python312\Lib\site-packages\django\shortcuts.py", line 24, in render
    content = loader.render_to_string(template_name, context, request, using=using)
              ^^^^^^^^^^^^^^^^^^^^^^^^^^^^^^^^^^^^^^^^^^^^^^^^^^^^^^^^^^^^^^^^^^^^^
  File "C:\Users\ASWANI\AppData\Local\Programs\Python\Python312\Lib\site-packages\django\template\loader.py", line 61, in render_to_string
    template = get_template(template_name, using=using)
               ^^^^^^^^^^^^^^^^^^^^^^^^^^^^^^^^^^^^^^^^
  File "C:\Users\ASWANI\AppData\Local\Programs\Python\Python312\Lib\site-packages\django\template\loader.py", line 15, in get_template
    return engine.get_template(template_name)
           ^^^^^^^^^^^^^^^^^^^^^^^^^^^^^^^^^^
  File "C:\Users\ASWANI\AppData\Local\Programs\Python\Python312\Lib\site-packages\django\template\backends\django.py", line 33, in get_template
    return Template(self.engine.get_template(template_name), self)
                    ^^^^^^^^^^^^^^^^^^^^^^^^^^^^^^^^^^^^^^^
  File "C:\Users\ASWANI\AppData\Local\Programs\Python\Python312\Lib\site-packages\django\template\engine.py", line 175, in get_template
    template, origin = self.find_template(template_name)
                       ^^^^^^^^^^^^^^^^^^^^^^^^^^^^^^^^^
  File "C:\Users\ASWANI\AppData\Local\Programs\Python\Python312\Lib\site-packages\django\template\engine.py", line 157, in find_template
    template = loader.get_template(name, skip=skip)
               ^^^^^^^^^^^^^^^^^^^^^^^^^^^^^^^^^^^^
  File "C:\Users\ASWANI\AppData\Local\Programs\Python\Python312\Lib\site-packages\django\template\loaders\cached.py", line 57, in get_template
    template = super().get_template(template_name, skip)
               ^^^^^^^^^^^^^^^^^^^^^^^^^^^^^^^^^^^^^^^^^
  File "C:\Users\ASWANI\AppData\Local\Programs\Python\Python312\Lib\site-packages\django\template\loaders\base.py", line 28, in get_template
    return Template(
           ^^^^^^^^^
  File "C:\Users\ASWANI\AppData\Local\Programs\Python\Python312\Lib\site-packages\django\template\base.py", line 154, in __init__
    self.nodelist = self.compile_nodelist()
                    ^^^^^^^^^^^^^^^^^^^^^^^
  File "C:\Users\ASWANI\AppData\Local\Programs\Python\Python312\Lib\site-packages\django\template\base.py", line 196, in compile_nodelist
    return parser.parse()
           ^^^^^^^^^^^^^^
  File "C:\Users\ASWANI\AppData\Local\Programs\Python\Python312\Lib\site-packages\django\template\base.py", line 510, in parse
    raise self.error(token, e)
  File "C:\Users\ASWANI\AppData\Local\Programs\Python\Python312\Lib\site-packages\django\template\base.py", line 508, in parse
    compiled_result = compile_func(self, token)
                      ^^^^^^^^^^^^^^^^^^^^^^^^^
  File "C:\Users\ASWANI\AppData\Local\Programs\Python\Python312\Lib\site-packages\django\template\loader_tags.py", line 295, in do_extends
    nodelist = parser.parse()
               ^^^^^^^^^^^^^^
  File "C:\Users\ASWANI\AppData\Local\Programs\Python\Python312\Lib\site-packages\django\template\base.py", line 510, in parse
    raise self.error(token, e)
  File "C:\Users\ASWANI\AppData\Local\Programs\Python\Python312\Lib\site-packages\django\template\base.py", line 508, in parse
    compiled_result = compile_func(self, token)
                      ^^^^^^^^^^^^^^^^^^^^^^^^^
  File "C:\Users\ASWANI\AppData\Local\Programs\Python\Python312\Lib\site-packages\django\template\loader_tags.py", line 234, in do_block
    nodelist = parser.parse(("endblock",))
               ^^^^^^^^^^^^^^^^^^^^^^^^^^^
  File "C:\Users\ASWANI\AppData\Local\Programs\Python\Python312\Lib\site-packages\django\template\base.py", line 504, in parse
    self.invalid_block_tag(token, command, parse_until)
  File "C:\Users\ASWANI\AppData\Local\Programs\Python\Python312\Lib\site-packages\django\template\base.py", line 555, in invalid_block_tag
    raise self.error(
django.template.exceptions.TemplateSyntaxError: Invalid block tag on line 27: 'endfor', expected 'endblock'. Did you forget to register or load this tag?
2024-06-11 13:35:44,707 - INFO - C:\Users\ASWANI\new prj-Trouble Tracker\trouble_tracker\trouble_app\views.py changed, reloading.
2024-06-11 13:35:54,508 - INFO - C:\Users\ASWANI\new prj-Trouble Tracker\trouble_tracker\trouble_app\views.py changed, reloading.
2024-06-11 13:38:39,099 - INFO - C:\Users\ASWANI\new prj-Trouble Tracker\trouble_tracker\trouble_app\views.py changed, reloading.
2024-06-11 13:38:41,499 - INFO - C:\Users\ASWANI\new prj-Trouble Tracker\trouble_tracker\trouble_app\views.py changed, reloading.
2024-06-11 13:40:15,035 - INFO - C:\Users\ASWANI\new prj-Trouble Tracker\trouble_tracker\trouble_app\views.py changed, reloading.
2024-06-11 13:40:20,520 - INFO - C:\Users\ASWANI\new prj-Trouble Tracker\trouble_tracker\trouble_app\views.py changed, reloading.
2024-06-11 13:42:41,241 - ERROR - Internal Server Error: /
Traceback (most recent call last):
  File "C:\Users\ASWANI\AppData\Local\Programs\Python\Python312\Lib\site-packages\django\core\handlers\exception.py", line 55, in inner
    response = get_response(request)
               ^^^^^^^^^^^^^^^^^^^^^
  File "C:\Users\ASWANI\AppData\Local\Programs\Python\Python312\Lib\site-packages\django\core\handlers\base.py", line 197, in _get_response
    response = wrapped_callback(request, *callback_args, **callback_kwargs)
               ^^^^^^^^^^^^^^^^^^^^^^^^^^^^^^^^^^^^^^^^^^^^^^^^^^^^^^^^^^^^
  File "C:\Users\ASWANI\AppData\Local\Programs\Python\Python312\Lib\site-packages\django\contrib\auth\decorators.py", line 23, in _wrapper_view
    return view_func(request, *args, **kwargs)
           ^^^^^^^^^^^^^^^^^^^^^^^^^^^^^^^^^^^
  File "C:\Users\ASWANI\new prj-Trouble Tracker\trouble_tracker\trouble_app\views.py", line 48, in index
    return render(request, 'index.html', {'issues': issues})
           ^^^^^^^^^^^^^^^^^^^^^^^^^^^^^^^^^^^^^^^^^^^^^^^^^
  File "C:\Users\ASWANI\AppData\Local\Programs\Python\Python312\Lib\site-packages\django\shortcuts.py", line 24, in render
    content = loader.render_to_string(template_name, context, request, using=using)
              ^^^^^^^^^^^^^^^^^^^^^^^^^^^^^^^^^^^^^^^^^^^^^^^^^^^^^^^^^^^^^^^^^^^^^
  File "C:\Users\ASWANI\AppData\Local\Programs\Python\Python312\Lib\site-packages\django\template\loader.py", line 62, in render_to_string
    return template.render(context, request)
           ^^^^^^^^^^^^^^^^^^^^^^^^^^^^^^^^^
  File "C:\Users\ASWANI\AppData\Local\Programs\Python\Python312\Lib\site-packages\django\template\backends\django.py", line 61, in render
    return self.template.render(context)
           ^^^^^^^^^^^^^^^^^^^^^^^^^^^^^
  File "C:\Users\ASWANI\AppData\Local\Programs\Python\Python312\Lib\site-packages\django\template\base.py", line 171, in render
    return self._render(context)
           ^^^^^^^^^^^^^^^^^^^^^
  File "C:\Users\ASWANI\AppData\Local\Programs\Python\Python312\Lib\site-packages\django\template\base.py", line 163, in _render
    return self.nodelist.render(context)
           ^^^^^^^^^^^^^^^^^^^^^^^^^^^^^
  File "C:\Users\ASWANI\AppData\Local\Programs\Python\Python312\Lib\site-packages\django\template\base.py", line 1000, in render
    return SafeString("".join([node.render_annotated(context) for node in self]))
                               ^^^^^^^^^^^^^^^^^^^^^^^^^^^^^^
  File "C:\Users\ASWANI\AppData\Local\Programs\Python\Python312\Lib\site-packages\django\template\base.py", line 961, in render_annotated
    return self.render(context)
           ^^^^^^^^^^^^^^^^^^^^
  File "C:\Users\ASWANI\AppData\Local\Programs\Python\Python312\Lib\site-packages\django\template\defaulttags.py", line 325, in render
    return nodelist.render(context)
           ^^^^^^^^^^^^^^^^^^^^^^^^
  File "C:\Users\ASWANI\AppData\Local\Programs\Python\Python312\Lib\site-packages\django\template\base.py", line 1000, in render
    return SafeString("".join([node.render_annotated(context) for node in self]))
                               ^^^^^^^^^^^^^^^^^^^^^^^^^^^^^^
  File "C:\Users\ASWANI\AppData\Local\Programs\Python\Python312\Lib\site-packages\django\template\base.py", line 961, in render_annotated
    return self.render(context)
           ^^^^^^^^^^^^^^^^^^^^
  File "C:\Users\ASWANI\AppData\Local\Programs\Python\Python312\Lib\site-packages\django\template\defaulttags.py", line 478, in render
    url = reverse(view_name, args=args, kwargs=kwargs, current_app=current_app)
          ^^^^^^^^^^^^^^^^^^^^^^^^^^^^^^^^^^^^^^^^^^^^^^^^^^^^^^^^^^^^^^^^^^^^^
  File "C:\Users\ASWANI\AppData\Local\Programs\Python\Python312\Lib\site-packages\django\urls\base.py", line 88, in reverse
    return resolver._reverse_with_prefix(view, prefix, *args, **kwargs)
           ^^^^^^^^^^^^^^^^^^^^^^^^^^^^^^^^^^^^^^^^^^^^^^^^^^^^^^^^^^^^
  File "C:\Users\ASWANI\AppData\Local\Programs\Python\Python312\Lib\site-packages\django\urls\resolvers.py", line 848, in _reverse_with_prefix
    raise NoReverseMatch(msg)
django.urls.exceptions.NoReverseMatch: Reverse for 'create_issue' not found. 'create_issue' is not a valid view function or pattern name.
2024-06-11 13:43:59,117 - INFO - C:\Users\ASWANI\new prj-Trouble Tracker\trouble_tracker\trouble_app\urls.py changed, reloading.
2024-06-11 13:44:01,638 - INFO - C:\Users\ASWANI\new prj-Trouble Tracker\trouble_tracker\trouble_app\urls.py changed, reloading.
2024-06-11 13:44:03,920 - INFO - C:\Users\ASWANI\new prj-Trouble Tracker\trouble_tracker\trouble_app\urls.py changed, reloading.
2024-06-11 13:46:02,114 - ERROR - Internal Server Error: /
Traceback (most recent call last):
  File "C:\Users\ASWANI\AppData\Local\Programs\Python\Python312\Lib\site-packages\django\core\handlers\exception.py", line 55, in inner
    response = get_response(request)
               ^^^^^^^^^^^^^^^^^^^^^
  File "C:\Users\ASWANI\AppData\Local\Programs\Python\Python312\Lib\site-packages\django\core\handlers\base.py", line 197, in _get_response
    response = wrapped_callback(request, *callback_args, **callback_kwargs)
               ^^^^^^^^^^^^^^^^^^^^^^^^^^^^^^^^^^^^^^^^^^^^^^^^^^^^^^^^^^^^
  File "C:\Users\ASWANI\AppData\Local\Programs\Python\Python312\Lib\site-packages\django\contrib\auth\decorators.py", line 23, in _wrapper_view
    return view_func(request, *args, **kwargs)
           ^^^^^^^^^^^^^^^^^^^^^^^^^^^^^^^^^^^
  File "C:\Users\ASWANI\new prj-Trouble Tracker\trouble_tracker\trouble_app\views.py", line 48, in index
    return render(request, 'index.html', {'issues': issues})
           ^^^^^^^^^^^^^^^^^^^^^^^^^^^^^^^^^^^^^^^^^^^^^^^^^
  File "C:\Users\ASWANI\AppData\Local\Programs\Python\Python312\Lib\site-packages\django\shortcuts.py", line 24, in render
    content = loader.render_to_string(template_name, context, request, using=using)
              ^^^^^^^^^^^^^^^^^^^^^^^^^^^^^^^^^^^^^^^^^^^^^^^^^^^^^^^^^^^^^^^^^^^^^
  File "C:\Users\ASWANI\AppData\Local\Programs\Python\Python312\Lib\site-packages\django\template\loader.py", line 62, in render_to_string
    return template.render(context, request)
           ^^^^^^^^^^^^^^^^^^^^^^^^^^^^^^^^^
  File "C:\Users\ASWANI\AppData\Local\Programs\Python\Python312\Lib\site-packages\django\template\backends\django.py", line 61, in render
    return self.template.render(context)
           ^^^^^^^^^^^^^^^^^^^^^^^^^^^^^
  File "C:\Users\ASWANI\AppData\Local\Programs\Python\Python312\Lib\site-packages\django\template\base.py", line 171, in render
    return self._render(context)
           ^^^^^^^^^^^^^^^^^^^^^
  File "C:\Users\ASWANI\AppData\Local\Programs\Python\Python312\Lib\site-packages\django\template\base.py", line 163, in _render
    return self.nodelist.render(context)
           ^^^^^^^^^^^^^^^^^^^^^^^^^^^^^
  File "C:\Users\ASWANI\AppData\Local\Programs\Python\Python312\Lib\site-packages\django\template\base.py", line 1000, in render
    return SafeString("".join([node.render_annotated(context) for node in self]))
                               ^^^^^^^^^^^^^^^^^^^^^^^^^^^^^^
  File "C:\Users\ASWANI\AppData\Local\Programs\Python\Python312\Lib\site-packages\django\template\base.py", line 961, in render_annotated
    return self.render(context)
           ^^^^^^^^^^^^^^^^^^^^
  File "C:\Users\ASWANI\AppData\Local\Programs\Python\Python312\Lib\site-packages\django\template\defaulttags.py", line 325, in render
    return nodelist.render(context)
           ^^^^^^^^^^^^^^^^^^^^^^^^
  File "C:\Users\ASWANI\AppData\Local\Programs\Python\Python312\Lib\site-packages\django\template\base.py", line 1000, in render
    return SafeString("".join([node.render_annotated(context) for node in self]))
                               ^^^^^^^^^^^^^^^^^^^^^^^^^^^^^^
  File "C:\Users\ASWANI\AppData\Local\Programs\Python\Python312\Lib\site-packages\django\template\base.py", line 961, in render_annotated
    return self.render(context)
           ^^^^^^^^^^^^^^^^^^^^
  File "C:\Users\ASWANI\AppData\Local\Programs\Python\Python312\Lib\site-packages\django\template\defaulttags.py", line 478, in render
    url = reverse(view_name, args=args, kwargs=kwargs, current_app=current_app)
          ^^^^^^^^^^^^^^^^^^^^^^^^^^^^^^^^^^^^^^^^^^^^^^^^^^^^^^^^^^^^^^^^^^^^^
  File "C:\Users\ASWANI\AppData\Local\Programs\Python\Python312\Lib\site-packages\django\urls\base.py", line 88, in reverse
    return resolver._reverse_with_prefix(view, prefix, *args, **kwargs)
           ^^^^^^^^^^^^^^^^^^^^^^^^^^^^^^^^^^^^^^^^^^^^^^^^^^^^^^^^^^^^
  File "C:\Users\ASWANI\AppData\Local\Programs\Python\Python312\Lib\site-packages\django\urls\resolvers.py", line 848, in _reverse_with_prefix
    raise NoReverseMatch(msg)
django.urls.exceptions.NoReverseMatch: Reverse for 'create_issue' not found. 'create_issue' is not a valid view function or pattern name.
2024-06-11 13:47:02,316 - ERROR - Internal Server Error: /
Traceback (most recent call last):
  File "C:\Users\ASWANI\AppData\Local\Programs\Python\Python312\Lib\site-packages\django\core\handlers\exception.py", line 55, in inner
    response = get_response(request)
               ^^^^^^^^^^^^^^^^^^^^^
  File "C:\Users\ASWANI\AppData\Local\Programs\Python\Python312\Lib\site-packages\django\core\handlers\base.py", line 197, in _get_response
    response = wrapped_callback(request, *callback_args, **callback_kwargs)
               ^^^^^^^^^^^^^^^^^^^^^^^^^^^^^^^^^^^^^^^^^^^^^^^^^^^^^^^^^^^^
  File "C:\Users\ASWANI\AppData\Local\Programs\Python\Python312\Lib\site-packages\django\contrib\auth\decorators.py", line 23, in _wrapper_view
    return view_func(request, *args, **kwargs)
           ^^^^^^^^^^^^^^^^^^^^^^^^^^^^^^^^^^^
  File "C:\Users\ASWANI\new prj-Trouble Tracker\trouble_tracker\trouble_app\views.py", line 48, in index
    return render(request, 'index.html', {'issues': issues})
           ^^^^^^^^^^^^^^^^^^^^^^^^^^^^^^^^^^^^^^^^^^^^^^^^^
  File "C:\Users\ASWANI\AppData\Local\Programs\Python\Python312\Lib\site-packages\django\shortcuts.py", line 24, in render
    content = loader.render_to_string(template_name, context, request, using=using)
              ^^^^^^^^^^^^^^^^^^^^^^^^^^^^^^^^^^^^^^^^^^^^^^^^^^^^^^^^^^^^^^^^^^^^^
  File "C:\Users\ASWANI\AppData\Local\Programs\Python\Python312\Lib\site-packages\django\template\loader.py", line 62, in render_to_string
    return template.render(context, request)
           ^^^^^^^^^^^^^^^^^^^^^^^^^^^^^^^^^
  File "C:\Users\ASWANI\AppData\Local\Programs\Python\Python312\Lib\site-packages\django\template\backends\django.py", line 61, in render
    return self.template.render(context)
           ^^^^^^^^^^^^^^^^^^^^^^^^^^^^^
  File "C:\Users\ASWANI\AppData\Local\Programs\Python\Python312\Lib\site-packages\django\template\base.py", line 171, in render
    return self._render(context)
           ^^^^^^^^^^^^^^^^^^^^^
  File "C:\Users\ASWANI\AppData\Local\Programs\Python\Python312\Lib\site-packages\django\template\base.py", line 163, in _render
    return self.nodelist.render(context)
           ^^^^^^^^^^^^^^^^^^^^^^^^^^^^^
  File "C:\Users\ASWANI\AppData\Local\Programs\Python\Python312\Lib\site-packages\django\template\base.py", line 1000, in render
    return SafeString("".join([node.render_annotated(context) for node in self]))
                               ^^^^^^^^^^^^^^^^^^^^^^^^^^^^^^
  File "C:\Users\ASWANI\AppData\Local\Programs\Python\Python312\Lib\site-packages\django\template\base.py", line 961, in render_annotated
    return self.render(context)
           ^^^^^^^^^^^^^^^^^^^^
  File "C:\Users\ASWANI\AppData\Local\Programs\Python\Python312\Lib\site-packages\django\template\defaulttags.py", line 325, in render
    return nodelist.render(context)
           ^^^^^^^^^^^^^^^^^^^^^^^^
  File "C:\Users\ASWANI\AppData\Local\Programs\Python\Python312\Lib\site-packages\django\template\base.py", line 1000, in render
    return SafeString("".join([node.render_annotated(context) for node in self]))
                               ^^^^^^^^^^^^^^^^^^^^^^^^^^^^^^
  File "C:\Users\ASWANI\AppData\Local\Programs\Python\Python312\Lib\site-packages\django\template\base.py", line 961, in render_annotated
    return self.render(context)
           ^^^^^^^^^^^^^^^^^^^^
  File "C:\Users\ASWANI\AppData\Local\Programs\Python\Python312\Lib\site-packages\django\template\defaulttags.py", line 478, in render
    url = reverse(view_name, args=args, kwargs=kwargs, current_app=current_app)
          ^^^^^^^^^^^^^^^^^^^^^^^^^^^^^^^^^^^^^^^^^^^^^^^^^^^^^^^^^^^^^^^^^^^^^
  File "C:\Users\ASWANI\AppData\Local\Programs\Python\Python312\Lib\site-packages\django\urls\base.py", line 88, in reverse
    return resolver._reverse_with_prefix(view, prefix, *args, **kwargs)
           ^^^^^^^^^^^^^^^^^^^^^^^^^^^^^^^^^^^^^^^^^^^^^^^^^^^^^^^^^^^^
  File "C:\Users\ASWANI\AppData\Local\Programs\Python\Python312\Lib\site-packages\django\urls\resolvers.py", line 848, in _reverse_with_prefix
    raise NoReverseMatch(msg)
django.urls.exceptions.NoReverseMatch: Reverse for 'create_issue' not found. 'create_issue' is not a valid view function or pattern name.
2024-06-11 13:48:21,114 - INFO - C:\Users\ASWANI\new prj-Trouble Tracker\trouble_tracker\trouble_app\views.py changed, reloading.
2024-06-11 13:49:09,844 - ERROR - Internal Server Error: /
Traceback (most recent call last):
  File "C:\Users\ASWANI\AppData\Local\Programs\Python\Python312\Lib\site-packages\django\core\handlers\exception.py", line 55, in inner
    response = get_response(request)
               ^^^^^^^^^^^^^^^^^^^^^
  File "C:\Users\ASWANI\AppData\Local\Programs\Python\Python312\Lib\site-packages\django\core\handlers\base.py", line 197, in _get_response
    response = wrapped_callback(request, *callback_args, **callback_kwargs)
               ^^^^^^^^^^^^^^^^^^^^^^^^^^^^^^^^^^^^^^^^^^^^^^^^^^^^^^^^^^^^
  File "C:\Users\ASWANI\AppData\Local\Programs\Python\Python312\Lib\site-packages\django\contrib\auth\decorators.py", line 23, in _wrapper_view
    return view_func(request, *args, **kwargs)
           ^^^^^^^^^^^^^^^^^^^^^^^^^^^^^^^^^^^
  File "C:\Users\ASWANI\new prj-Trouble Tracker\trouble_tracker\trouble_app\views.py", line 48, in index
    return render(request, 'index.html', {'issues': issues})
           ^^^^^^^^^^^^^^^^^^^^^^^^^^^^^^^^^^^^^^^^^^^^^^^^^
  File "C:\Users\ASWANI\AppData\Local\Programs\Python\Python312\Lib\site-packages\django\shortcuts.py", line 24, in render
    content = loader.render_to_string(template_name, context, request, using=using)
              ^^^^^^^^^^^^^^^^^^^^^^^^^^^^^^^^^^^^^^^^^^^^^^^^^^^^^^^^^^^^^^^^^^^^^
  File "C:\Users\ASWANI\AppData\Local\Programs\Python\Python312\Lib\site-packages\django\template\loader.py", line 62, in render_to_string
    return template.render(context, request)
           ^^^^^^^^^^^^^^^^^^^^^^^^^^^^^^^^^
  File "C:\Users\ASWANI\AppData\Local\Programs\Python\Python312\Lib\site-packages\django\template\backends\django.py", line 61, in render
    return self.template.render(context)
           ^^^^^^^^^^^^^^^^^^^^^^^^^^^^^
  File "C:\Users\ASWANI\AppData\Local\Programs\Python\Python312\Lib\site-packages\django\template\base.py", line 171, in render
    return self._render(context)
           ^^^^^^^^^^^^^^^^^^^^^
  File "C:\Users\ASWANI\AppData\Local\Programs\Python\Python312\Lib\site-packages\django\template\base.py", line 163, in _render
    return self.nodelist.render(context)
           ^^^^^^^^^^^^^^^^^^^^^^^^^^^^^
  File "C:\Users\ASWANI\AppData\Local\Programs\Python\Python312\Lib\site-packages\django\template\base.py", line 1000, in render
    return SafeString("".join([node.render_annotated(context) for node in self]))
                               ^^^^^^^^^^^^^^^^^^^^^^^^^^^^^^
  File "C:\Users\ASWANI\AppData\Local\Programs\Python\Python312\Lib\site-packages\django\template\base.py", line 961, in render_annotated
    return self.render(context)
           ^^^^^^^^^^^^^^^^^^^^
  File "C:\Users\ASWANI\AppData\Local\Programs\Python\Python312\Lib\site-packages\django\template\defaulttags.py", line 325, in render
    return nodelist.render(context)
           ^^^^^^^^^^^^^^^^^^^^^^^^
  File "C:\Users\ASWANI\AppData\Local\Programs\Python\Python312\Lib\site-packages\django\template\base.py", line 1000, in render
    return SafeString("".join([node.render_annotated(context) for node in self]))
                               ^^^^^^^^^^^^^^^^^^^^^^^^^^^^^^
  File "C:\Users\ASWANI\AppData\Local\Programs\Python\Python312\Lib\site-packages\django\template\base.py", line 961, in render_annotated
    return self.render(context)
           ^^^^^^^^^^^^^^^^^^^^
  File "C:\Users\ASWANI\AppData\Local\Programs\Python\Python312\Lib\site-packages\django\template\defaulttags.py", line 478, in render
    url = reverse(view_name, args=args, kwargs=kwargs, current_app=current_app)
          ^^^^^^^^^^^^^^^^^^^^^^^^^^^^^^^^^^^^^^^^^^^^^^^^^^^^^^^^^^^^^^^^^^^^^
  File "C:\Users\ASWANI\AppData\Local\Programs\Python\Python312\Lib\site-packages\django\urls\base.py", line 88, in reverse
    return resolver._reverse_with_prefix(view, prefix, *args, **kwargs)
           ^^^^^^^^^^^^^^^^^^^^^^^^^^^^^^^^^^^^^^^^^^^^^^^^^^^^^^^^^^^^
  File "C:\Users\ASWANI\AppData\Local\Programs\Python\Python312\Lib\site-packages\django\urls\resolvers.py", line 848, in _reverse_with_prefix
    raise NoReverseMatch(msg)
django.urls.exceptions.NoReverseMatch: Reverse for 'create_issue' not found. 'create_issue' is not a valid view function or pattern name.
2024-06-11 13:50:43,210 - INFO - C:\Users\ASWANI\new prj-Trouble Tracker\trouble_tracker\trouble_tracker\urls.py changed, reloading.
2024-06-11 13:50:49,694 - INFO - C:\Users\ASWANI\new prj-Trouble Tracker\trouble_tracker\trouble_tracker\urls.py changed, reloading.
2024-06-11 13:53:31,836 - ERROR - Internal Server Error: /issues/
Traceback (most recent call last):
  File "C:\Users\ASWANI\AppData\Local\Programs\Python\Python312\Lib\site-packages\django\template\base.py", line 502, in parse
    compile_func = self.tags[command]
                   ~~~~~~~~~^^^^^^^^^
KeyError: 'endfor'

During handling of the above exception, another exception occurred:

Traceback (most recent call last):
  File "C:\Users\ASWANI\AppData\Local\Programs\Python\Python312\Lib\site-packages\django\core\handlers\exception.py", line 55, in inner
    response = get_response(request)
               ^^^^^^^^^^^^^^^^^^^^^
  File "C:\Users\ASWANI\AppData\Local\Programs\Python\Python312\Lib\site-packages\django\core\handlers\base.py", line 197, in _get_response
    response = wrapped_callback(request, *callback_args, **callback_kwargs)
               ^^^^^^^^^^^^^^^^^^^^^^^^^^^^^^^^^^^^^^^^^^^^^^^^^^^^^^^^^^^^
  File "C:\Users\ASWANI\AppData\Local\Programs\Python\Python312\Lib\site-packages\django\contrib\auth\decorators.py", line 23, in _wrapper_view
    return view_func(request, *args, **kwargs)
           ^^^^^^^^^^^^^^^^^^^^^^^^^^^^^^^^^^^
  File "C:\Users\ASWANI\new prj-Trouble Tracker\trouble_tracker\trouble_app\views.py", line 81, in issue_list
    return render(request, 'issue_list.html', {'issues': issues})
           ^^^^^^^^^^^^^^^^^^^^^^^^^^^^^^^^^^^^^^^^^^^^^^^^^^^^^^
  File "C:\Users\ASWANI\AppData\Local\Programs\Python\Python312\Lib\site-packages\django\shortcuts.py", line 24, in render
    content = loader.render_to_string(template_name, context, request, using=using)
              ^^^^^^^^^^^^^^^^^^^^^^^^^^^^^^^^^^^^^^^^^^^^^^^^^^^^^^^^^^^^^^^^^^^^^
  File "C:\Users\ASWANI\AppData\Local\Programs\Python\Python312\Lib\site-packages\django\template\loader.py", line 61, in render_to_string
    template = get_template(template_name, using=using)
               ^^^^^^^^^^^^^^^^^^^^^^^^^^^^^^^^^^^^^^^^
  File "C:\Users\ASWANI\AppData\Local\Programs\Python\Python312\Lib\site-packages\django\template\loader.py", line 15, in get_template
    return engine.get_template(template_name)
           ^^^^^^^^^^^^^^^^^^^^^^^^^^^^^^^^^^
  File "C:\Users\ASWANI\AppData\Local\Programs\Python\Python312\Lib\site-packages\django\template\backends\django.py", line 33, in get_template
    return Template(self.engine.get_template(template_name), self)
                    ^^^^^^^^^^^^^^^^^^^^^^^^^^^^^^^^^^^^^^^
  File "C:\Users\ASWANI\AppData\Local\Programs\Python\Python312\Lib\site-packages\django\template\engine.py", line 175, in get_template
    template, origin = self.find_template(template_name)
                       ^^^^^^^^^^^^^^^^^^^^^^^^^^^^^^^^^
  File "C:\Users\ASWANI\AppData\Local\Programs\Python\Python312\Lib\site-packages\django\template\engine.py", line 157, in find_template
    template = loader.get_template(name, skip=skip)
               ^^^^^^^^^^^^^^^^^^^^^^^^^^^^^^^^^^^^
  File "C:\Users\ASWANI\AppData\Local\Programs\Python\Python312\Lib\site-packages\django\template\loaders\cached.py", line 57, in get_template
    template = super().get_template(template_name, skip)
               ^^^^^^^^^^^^^^^^^^^^^^^^^^^^^^^^^^^^^^^^^
  File "C:\Users\ASWANI\AppData\Local\Programs\Python\Python312\Lib\site-packages\django\template\loaders\base.py", line 28, in get_template
    return Template(
           ^^^^^^^^^
  File "C:\Users\ASWANI\AppData\Local\Programs\Python\Python312\Lib\site-packages\django\template\base.py", line 154, in __init__
    self.nodelist = self.compile_nodelist()
                    ^^^^^^^^^^^^^^^^^^^^^^^
  File "C:\Users\ASWANI\AppData\Local\Programs\Python\Python312\Lib\site-packages\django\template\base.py", line 196, in compile_nodelist
    return parser.parse()
           ^^^^^^^^^^^^^^
  File "C:\Users\ASWANI\AppData\Local\Programs\Python\Python312\Lib\site-packages\django\template\base.py", line 510, in parse
    raise self.error(token, e)
  File "C:\Users\ASWANI\AppData\Local\Programs\Python\Python312\Lib\site-packages\django\template\base.py", line 508, in parse
    compiled_result = compile_func(self, token)
                      ^^^^^^^^^^^^^^^^^^^^^^^^^
  File "C:\Users\ASWANI\AppData\Local\Programs\Python\Python312\Lib\site-packages\django\template\loader_tags.py", line 295, in do_extends
    nodelist = parser.parse()
               ^^^^^^^^^^^^^^
  File "C:\Users\ASWANI\AppData\Local\Programs\Python\Python312\Lib\site-packages\django\template\base.py", line 510, in parse
    raise self.error(token, e)
  File "C:\Users\ASWANI\AppData\Local\Programs\Python\Python312\Lib\site-packages\django\template\base.py", line 508, in parse
    compiled_result = compile_func(self, token)
                      ^^^^^^^^^^^^^^^^^^^^^^^^^
  File "C:\Users\ASWANI\AppData\Local\Programs\Python\Python312\Lib\site-packages\django\template\loader_tags.py", line 234, in do_block
    nodelist = parser.parse(("endblock",))
               ^^^^^^^^^^^^^^^^^^^^^^^^^^^
  File "C:\Users\ASWANI\AppData\Local\Programs\Python\Python312\Lib\site-packages\django\template\base.py", line 504, in parse
    self.invalid_block_tag(token, command, parse_until)
  File "C:\Users\ASWANI\AppData\Local\Programs\Python\Python312\Lib\site-packages\django\template\base.py", line 555, in invalid_block_tag
    raise self.error(
django.template.exceptions.TemplateSyntaxError: Invalid block tag on line 27: 'endfor', expected 'endblock'. Did you forget to register or load this tag?
2024-06-11 13:59:43,931 - ERROR - Internal Server Error: /create_issue/
Traceback (most recent call last):
  File "C:\Users\ASWANI\AppData\Local\Programs\Python\Python312\Lib\site-packages\django\db\backends\utils.py", line 105, in _execute
    return self.cursor.execute(sql, params)
           ^^^^^^^^^^^^^^^^^^^^^^^^^^^^^^^^
  File "C:\Users\ASWANI\AppData\Local\Programs\Python\Python312\Lib\site-packages\django\db\backends\mysql\base.py", line 75, in execute
    return self.cursor.execute(query, args)
           ^^^^^^^^^^^^^^^^^^^^^^^^^^^^^^^^
  File "C:\Users\ASWANI\AppData\Local\Programs\Python\Python312\Lib\site-packages\MySQLdb\cursors.py", line 179, in execute
    res = self._query(mogrified_query)
          ^^^^^^^^^^^^^^^^^^^^^^^^^^^^
  File "C:\Users\ASWANI\AppData\Local\Programs\Python\Python312\Lib\site-packages\MySQLdb\cursors.py", line 330, in _query
    db.query(q)
  File "C:\Users\ASWANI\AppData\Local\Programs\Python\Python312\Lib\site-packages\MySQLdb\connections.py", line 261, in query
    _mysql.connection.query(self, query)
MySQLdb.IntegrityError: (1062, "Duplicate entry 'issue_list.html-8' for key 'trouble_app_issue.trouble_app_issue_title_created_by_id_ce282d39_uniq'")

The above exception was the direct cause of the following exception:

Traceback (most recent call last):
  File "C:\Users\ASWANI\AppData\Local\Programs\Python\Python312\Lib\site-packages\django\core\handlers\exception.py", line 55, in inner
    response = get_response(request)
               ^^^^^^^^^^^^^^^^^^^^^
  File "C:\Users\ASWANI\AppData\Local\Programs\Python\Python312\Lib\site-packages\django\core\handlers\base.py", line 197, in _get_response
    response = wrapped_callback(request, *callback_args, **callback_kwargs)
               ^^^^^^^^^^^^^^^^^^^^^^^^^^^^^^^^^^^^^^^^^^^^^^^^^^^^^^^^^^^^
  File "C:\Users\ASWANI\AppData\Local\Programs\Python\Python312\Lib\site-packages\django\contrib\auth\decorators.py", line 23, in _wrapper_view
    return view_func(request, *args, **kwargs)
           ^^^^^^^^^^^^^^^^^^^^^^^^^^^^^^^^^^^
  File "C:\Users\ASWANI\new prj-Trouble Tracker\trouble_tracker\trouble_app\views.py", line 119, in create_issue
    issue.save()
  File "C:\Users\ASWANI\AppData\Local\Programs\Python\Python312\Lib\site-packages\django\db\models\base.py", line 822, in save
    self.save_base(
  File "C:\Users\ASWANI\AppData\Local\Programs\Python\Python312\Lib\site-packages\django\db\models\base.py", line 909, in save_base
    updated = self._save_table(
              ^^^^^^^^^^^^^^^^^
  File "C:\Users\ASWANI\AppData\Local\Programs\Python\Python312\Lib\site-packages\django\db\models\base.py", line 1067, in _save_table
    results = self._do_insert(
              ^^^^^^^^^^^^^^^^
  File "C:\Users\ASWANI\AppData\Local\Programs\Python\Python312\Lib\site-packages\django\db\models\base.py", line 1108, in _do_insert
    return manager._insert(
           ^^^^^^^^^^^^^^^^
  File "C:\Users\ASWANI\AppData\Local\Programs\Python\Python312\Lib\site-packages\django\db\models\manager.py", line 87, in manager_method
    return getattr(self.get_queryset(), name)(*args, **kwargs)
           ^^^^^^^^^^^^^^^^^^^^^^^^^^^^^^^^^^^^^^^^^^^^^^^^^^^
  File "C:\Users\ASWANI\AppData\Local\Programs\Python\Python312\Lib\site-packages\django\db\models\query.py", line 1845, in _insert
    return query.get_compiler(using=using).execute_sql(returning_fields)
           ^^^^^^^^^^^^^^^^^^^^^^^^^^^^^^^^^^^^^^^^^^^^^^^^^^^^^^^^^^^^^
  File "C:\Users\ASWANI\AppData\Local\Programs\Python\Python312\Lib\site-packages\django\db\models\sql\compiler.py", line 1823, in execute_sql
    cursor.execute(sql, params)
  File "C:\Users\ASWANI\AppData\Local\Programs\Python\Python312\Lib\site-packages\django\db\backends\utils.py", line 122, in execute
    return super().execute(sql, params)
           ^^^^^^^^^^^^^^^^^^^^^^^^^^^^
  File "C:\Users\ASWANI\AppData\Local\Programs\Python\Python312\Lib\site-packages\django\db\backends\utils.py", line 79, in execute
    return self._execute_with_wrappers(
           ^^^^^^^^^^^^^^^^^^^^^^^^^^^^
  File "C:\Users\ASWANI\AppData\Local\Programs\Python\Python312\Lib\site-packages\django\db\backends\utils.py", line 92, in _execute_with_wrappers
    return executor(sql, params, many, context)
           ^^^^^^^^^^^^^^^^^^^^^^^^^^^^^^^^^^^^
  File "C:\Users\ASWANI\AppData\Local\Programs\Python\Python312\Lib\site-packages\django\db\backends\utils.py", line 100, in _execute
    with self.db.wrap_database_errors:
  File "C:\Users\ASWANI\AppData\Local\Programs\Python\Python312\Lib\site-packages\django\db\utils.py", line 91, in __exit__
    raise dj_exc_value.with_traceback(traceback) from exc_value
  File "C:\Users\ASWANI\AppData\Local\Programs\Python\Python312\Lib\site-packages\django\db\backends\utils.py", line 105, in _execute
    return self.cursor.execute(sql, params)
           ^^^^^^^^^^^^^^^^^^^^^^^^^^^^^^^^
  File "C:\Users\ASWANI\AppData\Local\Programs\Python\Python312\Lib\site-packages\django\db\backends\mysql\base.py", line 75, in execute
    return self.cursor.execute(query, args)
           ^^^^^^^^^^^^^^^^^^^^^^^^^^^^^^^^
  File "C:\Users\ASWANI\AppData\Local\Programs\Python\Python312\Lib\site-packages\MySQLdb\cursors.py", line 179, in execute
    res = self._query(mogrified_query)
          ^^^^^^^^^^^^^^^^^^^^^^^^^^^^
  File "C:\Users\ASWANI\AppData\Local\Programs\Python\Python312\Lib\site-packages\MySQLdb\cursors.py", line 330, in _query
    db.query(q)
  File "C:\Users\ASWANI\AppData\Local\Programs\Python\Python312\Lib\site-packages\MySQLdb\connections.py", line 261, in query
    _mysql.connection.query(self, query)
django.db.utils.IntegrityError: (1062, "Duplicate entry 'issue_list.html-8' for key 'trouble_app_issue.trouble_app_issue_title_created_by_id_ce282d39_uniq'")
2024-06-11 14:00:07,646 - ERROR - Internal Server Error: /create_issue/
Traceback (most recent call last):
  File "C:\Users\ASWANI\AppData\Local\Programs\Python\Python312\Lib\site-packages\django\db\backends\utils.py", line 105, in _execute
    return self.cursor.execute(sql, params)
           ^^^^^^^^^^^^^^^^^^^^^^^^^^^^^^^^
  File "C:\Users\ASWANI\AppData\Local\Programs\Python\Python312\Lib\site-packages\django\db\backends\mysql\base.py", line 75, in execute
    return self.cursor.execute(query, args)
           ^^^^^^^^^^^^^^^^^^^^^^^^^^^^^^^^
  File "C:\Users\ASWANI\AppData\Local\Programs\Python\Python312\Lib\site-packages\MySQLdb\cursors.py", line 179, in execute
    res = self._query(mogrified_query)
          ^^^^^^^^^^^^^^^^^^^^^^^^^^^^
  File "C:\Users\ASWANI\AppData\Local\Programs\Python\Python312\Lib\site-packages\MySQLdb\cursors.py", line 330, in _query
    db.query(q)
  File "C:\Users\ASWANI\AppData\Local\Programs\Python\Python312\Lib\site-packages\MySQLdb\connections.py", line 261, in query
    _mysql.connection.query(self, query)
MySQLdb.IntegrityError: (1062, "Duplicate entry 'issue_list.html-8' for key 'trouble_app_issue.trouble_app_issue_title_created_by_id_ce282d39_uniq'")

The above exception was the direct cause of the following exception:

Traceback (most recent call last):
  File "C:\Users\ASWANI\AppData\Local\Programs\Python\Python312\Lib\site-packages\django\core\handlers\exception.py", line 55, in inner
    response = get_response(request)
               ^^^^^^^^^^^^^^^^^^^^^
  File "C:\Users\ASWANI\AppData\Local\Programs\Python\Python312\Lib\site-packages\django\core\handlers\base.py", line 197, in _get_response
    response = wrapped_callback(request, *callback_args, **callback_kwargs)
               ^^^^^^^^^^^^^^^^^^^^^^^^^^^^^^^^^^^^^^^^^^^^^^^^^^^^^^^^^^^^
  File "C:\Users\ASWANI\AppData\Local\Programs\Python\Python312\Lib\site-packages\django\contrib\auth\decorators.py", line 23, in _wrapper_view
    return view_func(request, *args, **kwargs)
           ^^^^^^^^^^^^^^^^^^^^^^^^^^^^^^^^^^^
  File "C:\Users\ASWANI\new prj-Trouble Tracker\trouble_tracker\trouble_app\views.py", line 119, in create_issue
    issue.save()
  File "C:\Users\ASWANI\AppData\Local\Programs\Python\Python312\Lib\site-packages\django\db\models\base.py", line 822, in save
    self.save_base(
  File "C:\Users\ASWANI\AppData\Local\Programs\Python\Python312\Lib\site-packages\django\db\models\base.py", line 909, in save_base
    updated = self._save_table(
              ^^^^^^^^^^^^^^^^^
  File "C:\Users\ASWANI\AppData\Local\Programs\Python\Python312\Lib\site-packages\django\db\models\base.py", line 1067, in _save_table
    results = self._do_insert(
              ^^^^^^^^^^^^^^^^
  File "C:\Users\ASWANI\AppData\Local\Programs\Python\Python312\Lib\site-packages\django\db\models\base.py", line 1108, in _do_insert
    return manager._insert(
           ^^^^^^^^^^^^^^^^
  File "C:\Users\ASWANI\AppData\Local\Programs\Python\Python312\Lib\site-packages\django\db\models\manager.py", line 87, in manager_method
    return getattr(self.get_queryset(), name)(*args, **kwargs)
           ^^^^^^^^^^^^^^^^^^^^^^^^^^^^^^^^^^^^^^^^^^^^^^^^^^^
  File "C:\Users\ASWANI\AppData\Local\Programs\Python\Python312\Lib\site-packages\django\db\models\query.py", line 1845, in _insert
    return query.get_compiler(using=using).execute_sql(returning_fields)
           ^^^^^^^^^^^^^^^^^^^^^^^^^^^^^^^^^^^^^^^^^^^^^^^^^^^^^^^^^^^^^
  File "C:\Users\ASWANI\AppData\Local\Programs\Python\Python312\Lib\site-packages\django\db\models\sql\compiler.py", line 1823, in execute_sql
    cursor.execute(sql, params)
  File "C:\Users\ASWANI\AppData\Local\Programs\Python\Python312\Lib\site-packages\django\db\backends\utils.py", line 122, in execute
    return super().execute(sql, params)
           ^^^^^^^^^^^^^^^^^^^^^^^^^^^^
  File "C:\Users\ASWANI\AppData\Local\Programs\Python\Python312\Lib\site-packages\django\db\backends\utils.py", line 79, in execute
    return self._execute_with_wrappers(
           ^^^^^^^^^^^^^^^^^^^^^^^^^^^^
  File "C:\Users\ASWANI\AppData\Local\Programs\Python\Python312\Lib\site-packages\django\db\backends\utils.py", line 92, in _execute_with_wrappers
    return executor(sql, params, many, context)
           ^^^^^^^^^^^^^^^^^^^^^^^^^^^^^^^^^^^^
  File "C:\Users\ASWANI\AppData\Local\Programs\Python\Python312\Lib\site-packages\django\db\backends\utils.py", line 100, in _execute
    with self.db.wrap_database_errors:
  File "C:\Users\ASWANI\AppData\Local\Programs\Python\Python312\Lib\site-packages\django\db\utils.py", line 91, in __exit__
    raise dj_exc_value.with_traceback(traceback) from exc_value
  File "C:\Users\ASWANI\AppData\Local\Programs\Python\Python312\Lib\site-packages\django\db\backends\utils.py", line 105, in _execute
    return self.cursor.execute(sql, params)
           ^^^^^^^^^^^^^^^^^^^^^^^^^^^^^^^^
  File "C:\Users\ASWANI\AppData\Local\Programs\Python\Python312\Lib\site-packages\django\db\backends\mysql\base.py", line 75, in execute
    return self.cursor.execute(query, args)
           ^^^^^^^^^^^^^^^^^^^^^^^^^^^^^^^^
  File "C:\Users\ASWANI\AppData\Local\Programs\Python\Python312\Lib\site-packages\MySQLdb\cursors.py", line 179, in execute
    res = self._query(mogrified_query)
          ^^^^^^^^^^^^^^^^^^^^^^^^^^^^
  File "C:\Users\ASWANI\AppData\Local\Programs\Python\Python312\Lib\site-packages\MySQLdb\cursors.py", line 330, in _query
    db.query(q)
  File "C:\Users\ASWANI\AppData\Local\Programs\Python\Python312\Lib\site-packages\MySQLdb\connections.py", line 261, in query
    _mysql.connection.query(self, query)
django.db.utils.IntegrityError: (1062, "Duplicate entry 'issue_list.html-8' for key 'trouble_app_issue.trouble_app_issue_title_created_by_id_ce282d39_uniq'")
2024-06-11 14:02:42,151 - INFO - C:\Users\ASWANI\new prj-Trouble Tracker\trouble_tracker\trouble_app\views.py changed, reloading.
2024-06-11 14:02:56,894 - INFO - C:\Users\ASWANI\new prj-Trouble Tracker\trouble_tracker\trouble_app\views.py changed, reloading.
2024-06-11 14:03:03,189 - INFO - C:\Users\ASWANI\new prj-Trouble Tracker\trouble_tracker\trouble_app\views.py changed, reloading.
2024-06-11 14:04:07,319 - ERROR - Internal Server Error: /create_issue/
Traceback (most recent call last):
  File "C:\Users\ASWANI\AppData\Local\Programs\Python\Python312\Lib\site-packages\django\db\backends\utils.py", line 105, in _execute
    return self.cursor.execute(sql, params)
           ^^^^^^^^^^^^^^^^^^^^^^^^^^^^^^^^
  File "C:\Users\ASWANI\AppData\Local\Programs\Python\Python312\Lib\site-packages\django\db\backends\mysql\base.py", line 75, in execute
    return self.cursor.execute(query, args)
           ^^^^^^^^^^^^^^^^^^^^^^^^^^^^^^^^
  File "C:\Users\ASWANI\AppData\Local\Programs\Python\Python312\Lib\site-packages\MySQLdb\cursors.py", line 179, in execute
    res = self._query(mogrified_query)
          ^^^^^^^^^^^^^^^^^^^^^^^^^^^^
  File "C:\Users\ASWANI\AppData\Local\Programs\Python\Python312\Lib\site-packages\MySQLdb\cursors.py", line 330, in _query
    db.query(q)
  File "C:\Users\ASWANI\AppData\Local\Programs\Python\Python312\Lib\site-packages\MySQLdb\connections.py", line 261, in query
    _mysql.connection.query(self, query)
MySQLdb.IntegrityError: (1062, "Duplicate entry 'issue_list.html-8' for key 'trouble_app_issue.trouble_app_issue_title_created_by_id_ce282d39_uniq'")

The above exception was the direct cause of the following exception:

Traceback (most recent call last):
  File "C:\Users\ASWANI\AppData\Local\Programs\Python\Python312\Lib\site-packages\django\core\handlers\exception.py", line 55, in inner
    response = get_response(request)
               ^^^^^^^^^^^^^^^^^^^^^
  File "C:\Users\ASWANI\AppData\Local\Programs\Python\Python312\Lib\site-packages\django\core\handlers\base.py", line 197, in _get_response
    response = wrapped_callback(request, *callback_args, **callback_kwargs)
               ^^^^^^^^^^^^^^^^^^^^^^^^^^^^^^^^^^^^^^^^^^^^^^^^^^^^^^^^^^^^
  File "C:\Users\ASWANI\AppData\Local\Programs\Python\Python312\Lib\site-packages\django\contrib\auth\decorators.py", line 23, in _wrapper_view
    return view_func(request, *args, **kwargs)
           ^^^^^^^^^^^^^^^^^^^^^^^^^^^^^^^^^^^
  File "C:\Users\ASWANI\new prj-Trouble Tracker\trouble_tracker\trouble_app\views.py", line 119, in create_issue
    new_issue.save()
  File "C:\Users\ASWANI\AppData\Local\Programs\Python\Python312\Lib\site-packages\django\db\models\base.py", line 822, in save
    self.save_base(
  File "C:\Users\ASWANI\AppData\Local\Programs\Python\Python312\Lib\site-packages\django\db\models\base.py", line 909, in save_base
    updated = self._save_table(
              ^^^^^^^^^^^^^^^^^
  File "C:\Users\ASWANI\AppData\Local\Programs\Python\Python312\Lib\site-packages\django\db\models\base.py", line 1067, in _save_table
    results = self._do_insert(
              ^^^^^^^^^^^^^^^^
  File "C:\Users\ASWANI\AppData\Local\Programs\Python\Python312\Lib\site-packages\django\db\models\base.py", line 1108, in _do_insert
    return manager._insert(
           ^^^^^^^^^^^^^^^^
  File "C:\Users\ASWANI\AppData\Local\Programs\Python\Python312\Lib\site-packages\django\db\models\manager.py", line 87, in manager_method
    return getattr(self.get_queryset(), name)(*args, **kwargs)
           ^^^^^^^^^^^^^^^^^^^^^^^^^^^^^^^^^^^^^^^^^^^^^^^^^^^
  File "C:\Users\ASWANI\AppData\Local\Programs\Python\Python312\Lib\site-packages\django\db\models\query.py", line 1845, in _insert
    return query.get_compiler(using=using).execute_sql(returning_fields)
           ^^^^^^^^^^^^^^^^^^^^^^^^^^^^^^^^^^^^^^^^^^^^^^^^^^^^^^^^^^^^^
  File "C:\Users\ASWANI\AppData\Local\Programs\Python\Python312\Lib\site-packages\django\db\models\sql\compiler.py", line 1823, in execute_sql
    cursor.execute(sql, params)
  File "C:\Users\ASWANI\AppData\Local\Programs\Python\Python312\Lib\site-packages\django\db\backends\utils.py", line 122, in execute
    return super().execute(sql, params)
           ^^^^^^^^^^^^^^^^^^^^^^^^^^^^
  File "C:\Users\ASWANI\AppData\Local\Programs\Python\Python312\Lib\site-packages\django\db\backends\utils.py", line 79, in execute
    return self._execute_with_wrappers(
           ^^^^^^^^^^^^^^^^^^^^^^^^^^^^
  File "C:\Users\ASWANI\AppData\Local\Programs\Python\Python312\Lib\site-packages\django\db\backends\utils.py", line 92, in _execute_with_wrappers
    return executor(sql, params, many, context)
           ^^^^^^^^^^^^^^^^^^^^^^^^^^^^^^^^^^^^
  File "C:\Users\ASWANI\AppData\Local\Programs\Python\Python312\Lib\site-packages\django\db\backends\utils.py", line 100, in _execute
    with self.db.wrap_database_errors:
  File "C:\Users\ASWANI\AppData\Local\Programs\Python\Python312\Lib\site-packages\django\db\utils.py", line 91, in __exit__
    raise dj_exc_value.with_traceback(traceback) from exc_value
  File "C:\Users\ASWANI\AppData\Local\Programs\Python\Python312\Lib\site-packages\django\db\backends\utils.py", line 105, in _execute
    return self.cursor.execute(sql, params)
           ^^^^^^^^^^^^^^^^^^^^^^^^^^^^^^^^
  File "C:\Users\ASWANI\AppData\Local\Programs\Python\Python312\Lib\site-packages\django\db\backends\mysql\base.py", line 75, in execute
    return self.cursor.execute(query, args)
           ^^^^^^^^^^^^^^^^^^^^^^^^^^^^^^^^
  File "C:\Users\ASWANI\AppData\Local\Programs\Python\Python312\Lib\site-packages\MySQLdb\cursors.py", line 179, in execute
    res = self._query(mogrified_query)
          ^^^^^^^^^^^^^^^^^^^^^^^^^^^^
  File "C:\Users\ASWANI\AppData\Local\Programs\Python\Python312\Lib\site-packages\MySQLdb\cursors.py", line 330, in _query
    db.query(q)
  File "C:\Users\ASWANI\AppData\Local\Programs\Python\Python312\Lib\site-packages\MySQLdb\connections.py", line 261, in query
    _mysql.connection.query(self, query)
django.db.utils.IntegrityError: (1062, "Duplicate entry 'issue_list.html-8' for key 'trouble_app_issue.trouble_app_issue_title_created_by_id_ce282d39_uniq'")
2024-06-11 14:05:17,551 - INFO - C:\Users\ASWANI\new prj-Trouble Tracker\trouble_tracker\trouble_app\views.py changed, reloading.
2024-06-11 14:05:52,787 - ERROR - Internal Server Error: /create_issue/
Traceback (most recent call last):
  File "C:\Users\ASWANI\AppData\Local\Programs\Python\Python312\Lib\site-packages\django\core\handlers\exception.py", line 55, in inner
    response = get_response(request)
               ^^^^^^^^^^^^^^^^^^^^^
  File "C:\Users\ASWANI\AppData\Local\Programs\Python\Python312\Lib\site-packages\django\core\handlers\base.py", line 197, in _get_response
    response = wrapped_callback(request, *callback_args, **callback_kwargs)
               ^^^^^^^^^^^^^^^^^^^^^^^^^^^^^^^^^^^^^^^^^^^^^^^^^^^^^^^^^^^^
  File "C:\Users\ASWANI\new prj-Trouble Tracker\trouble_tracker\trouble_app\views.py", line 119, in create_issue
    created_by = form.cleaned_data['created_by']
                 ~~~~~~~~~~~~~~~~~^^^^^^^^^^^^^^
KeyError: 'created_by'
2024-06-11 14:07:14,738 - INFO - C:\Users\ASWANI\new prj-Trouble Tracker\trouble_tracker\trouble_app\forms.py changed, reloading.
2024-06-11 14:07:17,159 - INFO - C:\Users\ASWANI\new prj-Trouble Tracker\trouble_tracker\trouble_app\forms.py changed, reloading.
2024-06-11 14:07:20,520 - INFO - C:\Users\ASWANI\new prj-Trouble Tracker\trouble_tracker\trouble_app\forms.py changed, reloading.
2024-06-11 14:08:28,317 - INFO - C:\Users\ASWANI\new prj-Trouble Tracker\trouble_tracker\trouble_app\views.py changed, reloading.
2024-06-11 14:08:41,960 - INFO - C:\Users\ASWANI\new prj-Trouble Tracker\trouble_tracker\trouble_app\views.py changed, reloading.
2024-06-11 14:09:01,547 - INFO - C:\Users\ASWANI\new prj-Trouble Tracker\trouble_tracker\trouble_app\views.py changed, reloading.
2024-06-11 14:09:19,969 - ERROR - Internal Server Error: /create_issue/
Traceback (most recent call last):
  File "C:\Users\ASWANI\AppData\Local\Programs\Python\Python312\Lib\site-packages\django\db\backends\utils.py", line 105, in _execute
    return self.cursor.execute(sql, params)
           ^^^^^^^^^^^^^^^^^^^^^^^^^^^^^^^^
  File "C:\Users\ASWANI\AppData\Local\Programs\Python\Python312\Lib\site-packages\django\db\backends\mysql\base.py", line 75, in execute
    return self.cursor.execute(query, args)
           ^^^^^^^^^^^^^^^^^^^^^^^^^^^^^^^^
  File "C:\Users\ASWANI\AppData\Local\Programs\Python\Python312\Lib\site-packages\MySQLdb\cursors.py", line 179, in execute
    res = self._query(mogrified_query)
          ^^^^^^^^^^^^^^^^^^^^^^^^^^^^
  File "C:\Users\ASWANI\AppData\Local\Programs\Python\Python312\Lib\site-packages\MySQLdb\cursors.py", line 330, in _query
    db.query(q)
  File "C:\Users\ASWANI\AppData\Local\Programs\Python\Python312\Lib\site-packages\MySQLdb\connections.py", line 261, in query
    _mysql.connection.query(self, query)
MySQLdb.IntegrityError: (1048, "Column 'created_by_id' cannot be null")

The above exception was the direct cause of the following exception:

Traceback (most recent call last):
  File "C:\Users\ASWANI\AppData\Local\Programs\Python\Python312\Lib\site-packages\django\core\handlers\exception.py", line 55, in inner
    response = get_response(request)
               ^^^^^^^^^^^^^^^^^^^^^
  File "C:\Users\ASWANI\AppData\Local\Programs\Python\Python312\Lib\site-packages\django\core\handlers\base.py", line 197, in _get_response
    response = wrapped_callback(request, *callback_args, **callback_kwargs)
               ^^^^^^^^^^^^^^^^^^^^^^^^^^^^^^^^^^^^^^^^^^^^^^^^^^^^^^^^^^^^
  File "C:\Users\ASWANI\AppData\Local\Programs\Python\Python312\Lib\site-packages\django\contrib\auth\decorators.py", line 23, in _wrapper_view
    return view_func(request, *args, **kwargs)
           ^^^^^^^^^^^^^^^^^^^^^^^^^^^^^^^^^^^
  File "C:\Users\ASWANI\new prj-Trouble Tracker\trouble_tracker\trouble_app\views.py", line 124, in create_issue
    new_issue.save()
  File "C:\Users\ASWANI\AppData\Local\Programs\Python\Python312\Lib\site-packages\django\db\models\base.py", line 822, in save
    self.save_base(
  File "C:\Users\ASWANI\AppData\Local\Programs\Python\Python312\Lib\site-packages\django\db\models\base.py", line 909, in save_base
    updated = self._save_table(
              ^^^^^^^^^^^^^^^^^
  File "C:\Users\ASWANI\AppData\Local\Programs\Python\Python312\Lib\site-packages\django\db\models\base.py", line 1067, in _save_table
    results = self._do_insert(
              ^^^^^^^^^^^^^^^^
  File "C:\Users\ASWANI\AppData\Local\Programs\Python\Python312\Lib\site-packages\django\db\models\base.py", line 1108, in _do_insert
    return manager._insert(
           ^^^^^^^^^^^^^^^^
  File "C:\Users\ASWANI\AppData\Local\Programs\Python\Python312\Lib\site-packages\django\db\models\manager.py", line 87, in manager_method
    return getattr(self.get_queryset(), name)(*args, **kwargs)
           ^^^^^^^^^^^^^^^^^^^^^^^^^^^^^^^^^^^^^^^^^^^^^^^^^^^
  File "C:\Users\ASWANI\AppData\Local\Programs\Python\Python312\Lib\site-packages\django\db\models\query.py", line 1845, in _insert
    return query.get_compiler(using=using).execute_sql(returning_fields)
           ^^^^^^^^^^^^^^^^^^^^^^^^^^^^^^^^^^^^^^^^^^^^^^^^^^^^^^^^^^^^^
  File "C:\Users\ASWANI\AppData\Local\Programs\Python\Python312\Lib\site-packages\django\db\models\sql\compiler.py", line 1823, in execute_sql
    cursor.execute(sql, params)
  File "C:\Users\ASWANI\AppData\Local\Programs\Python\Python312\Lib\site-packages\django\db\backends\utils.py", line 122, in execute
    return super().execute(sql, params)
           ^^^^^^^^^^^^^^^^^^^^^^^^^^^^
  File "C:\Users\ASWANI\AppData\Local\Programs\Python\Python312\Lib\site-packages\django\db\backends\utils.py", line 79, in execute
    return self._execute_with_wrappers(
           ^^^^^^^^^^^^^^^^^^^^^^^^^^^^
  File "C:\Users\ASWANI\AppData\Local\Programs\Python\Python312\Lib\site-packages\django\db\backends\utils.py", line 92, in _execute_with_wrappers
    return executor(sql, params, many, context)
           ^^^^^^^^^^^^^^^^^^^^^^^^^^^^^^^^^^^^
  File "C:\Users\ASWANI\AppData\Local\Programs\Python\Python312\Lib\site-packages\django\db\backends\utils.py", line 100, in _execute
    with self.db.wrap_database_errors:
  File "C:\Users\ASWANI\AppData\Local\Programs\Python\Python312\Lib\site-packages\django\db\utils.py", line 91, in __exit__
    raise dj_exc_value.with_traceback(traceback) from exc_value
  File "C:\Users\ASWANI\AppData\Local\Programs\Python\Python312\Lib\site-packages\django\db\backends\utils.py", line 105, in _execute
    return self.cursor.execute(sql, params)
           ^^^^^^^^^^^^^^^^^^^^^^^^^^^^^^^^
  File "C:\Users\ASWANI\AppData\Local\Programs\Python\Python312\Lib\site-packages\django\db\backends\mysql\base.py", line 75, in execute
    return self.cursor.execute(query, args)
           ^^^^^^^^^^^^^^^^^^^^^^^^^^^^^^^^
  File "C:\Users\ASWANI\AppData\Local\Programs\Python\Python312\Lib\site-packages\MySQLdb\cursors.py", line 179, in execute
    res = self._query(mogrified_query)
          ^^^^^^^^^^^^^^^^^^^^^^^^^^^^
  File "C:\Users\ASWANI\AppData\Local\Programs\Python\Python312\Lib\site-packages\MySQLdb\cursors.py", line 330, in _query
    db.query(q)
  File "C:\Users\ASWANI\AppData\Local\Programs\Python\Python312\Lib\site-packages\MySQLdb\connections.py", line 261, in query
    _mysql.connection.query(self, query)
django.db.utils.IntegrityError: (1048, "Column 'created_by_id' cannot be null")
2024-06-11 14:10:15,374 - INFO - C:\Users\ASWANI\new prj-Trouble Tracker\trouble_tracker\trouble_app\views.py changed, reloading.
2024-06-11 14:10:22,599 - INFO - C:\Users\ASWANI\new prj-Trouble Tracker\trouble_tracker\trouble_app\views.py changed, reloading.
2024-06-11 14:11:22,366 - INFO - C:\Users\ASWANI\new prj-Trouble Tracker\trouble_tracker\trouble_app\forms.py changed, reloading.
2024-06-11 14:11:41,242 - ERROR - Internal Server Error: /create_issue/
Traceback (most recent call last):
  File "C:\Users\ASWANI\AppData\Local\Programs\Python\Python312\Lib\site-packages\django\db\backends\utils.py", line 105, in _execute
    return self.cursor.execute(sql, params)
           ^^^^^^^^^^^^^^^^^^^^^^^^^^^^^^^^
  File "C:\Users\ASWANI\AppData\Local\Programs\Python\Python312\Lib\site-packages\django\db\backends\mysql\base.py", line 75, in execute
    return self.cursor.execute(query, args)
           ^^^^^^^^^^^^^^^^^^^^^^^^^^^^^^^^
  File "C:\Users\ASWANI\AppData\Local\Programs\Python\Python312\Lib\site-packages\MySQLdb\cursors.py", line 179, in execute
    res = self._query(mogrified_query)
          ^^^^^^^^^^^^^^^^^^^^^^^^^^^^
  File "C:\Users\ASWANI\AppData\Local\Programs\Python\Python312\Lib\site-packages\MySQLdb\cursors.py", line 330, in _query
    db.query(q)
  File "C:\Users\ASWANI\AppData\Local\Programs\Python\Python312\Lib\site-packages\MySQLdb\connections.py", line 261, in query
    _mysql.connection.query(self, query)
MySQLdb.IntegrityError: (1062, "Duplicate entry 'issue_list.html-8' for key 'trouble_app_issue.trouble_app_issue_title_created_by_id_ce282d39_uniq'")

The above exception was the direct cause of the following exception:

Traceback (most recent call last):
  File "C:\Users\ASWANI\AppData\Local\Programs\Python\Python312\Lib\site-packages\django\core\handlers\exception.py", line 55, in inner
    response = get_response(request)
               ^^^^^^^^^^^^^^^^^^^^^
  File "C:\Users\ASWANI\AppData\Local\Programs\Python\Python312\Lib\site-packages\django\core\handlers\base.py", line 197, in _get_response
    response = wrapped_callback(request, *callback_args, **callback_kwargs)
               ^^^^^^^^^^^^^^^^^^^^^^^^^^^^^^^^^^^^^^^^^^^^^^^^^^^^^^^^^^^^
  File "C:\Users\ASWANI\AppData\Local\Programs\Python\Python312\Lib\site-packages\django\contrib\auth\decorators.py", line 23, in _wrapper_view
    return view_func(request, *args, **kwargs)
           ^^^^^^^^^^^^^^^^^^^^^^^^^^^^^^^^^^^
  File "C:\Users\ASWANI\new prj-Trouble Tracker\trouble_tracker\trouble_app\views.py", line 120, in create_issue
    new_issue.save()
  File "C:\Users\ASWANI\AppData\Local\Programs\Python\Python312\Lib\site-packages\django\db\models\base.py", line 822, in save
    self.save_base(
  File "C:\Users\ASWANI\AppData\Local\Programs\Python\Python312\Lib\site-packages\django\db\models\base.py", line 909, in save_base
    updated = self._save_table(
              ^^^^^^^^^^^^^^^^^
  File "C:\Users\ASWANI\AppData\Local\Programs\Python\Python312\Lib\site-packages\django\db\models\base.py", line 1067, in _save_table
    results = self._do_insert(
              ^^^^^^^^^^^^^^^^
  File "C:\Users\ASWANI\AppData\Local\Programs\Python\Python312\Lib\site-packages\django\db\models\base.py", line 1108, in _do_insert
    return manager._insert(
           ^^^^^^^^^^^^^^^^
  File "C:\Users\ASWANI\AppData\Local\Programs\Python\Python312\Lib\site-packages\django\db\models\manager.py", line 87, in manager_method
    return getattr(self.get_queryset(), name)(*args, **kwargs)
           ^^^^^^^^^^^^^^^^^^^^^^^^^^^^^^^^^^^^^^^^^^^^^^^^^^^
  File "C:\Users\ASWANI\AppData\Local\Programs\Python\Python312\Lib\site-packages\django\db\models\query.py", line 1845, in _insert
    return query.get_compiler(using=using).execute_sql(returning_fields)
           ^^^^^^^^^^^^^^^^^^^^^^^^^^^^^^^^^^^^^^^^^^^^^^^^^^^^^^^^^^^^^
  File "C:\Users\ASWANI\AppData\Local\Programs\Python\Python312\Lib\site-packages\django\db\models\sql\compiler.py", line 1823, in execute_sql
    cursor.execute(sql, params)
  File "C:\Users\ASWANI\AppData\Local\Programs\Python\Python312\Lib\site-packages\django\db\backends\utils.py", line 122, in execute
    return super().execute(sql, params)
           ^^^^^^^^^^^^^^^^^^^^^^^^^^^^
  File "C:\Users\ASWANI\AppData\Local\Programs\Python\Python312\Lib\site-packages\django\db\backends\utils.py", line 79, in execute
    return self._execute_with_wrappers(
           ^^^^^^^^^^^^^^^^^^^^^^^^^^^^
  File "C:\Users\ASWANI\AppData\Local\Programs\Python\Python312\Lib\site-packages\django\db\backends\utils.py", line 92, in _execute_with_wrappers
    return executor(sql, params, many, context)
           ^^^^^^^^^^^^^^^^^^^^^^^^^^^^^^^^^^^^
  File "C:\Users\ASWANI\AppData\Local\Programs\Python\Python312\Lib\site-packages\django\db\backends\utils.py", line 100, in _execute
    with self.db.wrap_database_errors:
  File "C:\Users\ASWANI\AppData\Local\Programs\Python\Python312\Lib\site-packages\django\db\utils.py", line 91, in __exit__
    raise dj_exc_value.with_traceback(traceback) from exc_value
  File "C:\Users\ASWANI\AppData\Local\Programs\Python\Python312\Lib\site-packages\django\db\backends\utils.py", line 105, in _execute
    return self.cursor.execute(sql, params)
           ^^^^^^^^^^^^^^^^^^^^^^^^^^^^^^^^
  File "C:\Users\ASWANI\AppData\Local\Programs\Python\Python312\Lib\site-packages\django\db\backends\mysql\base.py", line 75, in execute
    return self.cursor.execute(query, args)
           ^^^^^^^^^^^^^^^^^^^^^^^^^^^^^^^^
  File "C:\Users\ASWANI\AppData\Local\Programs\Python\Python312\Lib\site-packages\MySQLdb\cursors.py", line 179, in execute
    res = self._query(mogrified_query)
          ^^^^^^^^^^^^^^^^^^^^^^^^^^^^
  File "C:\Users\ASWANI\AppData\Local\Programs\Python\Python312\Lib\site-packages\MySQLdb\cursors.py", line 330, in _query
    db.query(q)
  File "C:\Users\ASWANI\AppData\Local\Programs\Python\Python312\Lib\site-packages\MySQLdb\connections.py", line 261, in query
    _mysql.connection.query(self, query)
django.db.utils.IntegrityError: (1062, "Duplicate entry 'issue_list.html-8' for key 'trouble_app_issue.trouble_app_issue_title_created_by_id_ce282d39_uniq'")
2024-06-11 14:13:01,689 - INFO - C:\Users\ASWANI\new prj-Trouble Tracker\trouble_tracker\trouble_app\admin.py changed, reloading.
2024-06-11 14:13:31,874 - INFO - C:\Users\ASWANI\new prj-Trouble Tracker\trouble_tracker\trouble_app\views.py changed, reloading.
2024-06-11 14:13:52,828 - INFO - C:\Users\ASWANI\new prj-Trouble Tracker\trouble_tracker\trouble_app\views.py changed, reloading.
2024-06-11 14:14:59,204 - INFO - C:\Users\ASWANI\new prj-Trouble Tracker\trouble_tracker\trouble_app\views.py changed, reloading.
2024-06-11 14:15:05,888 - INFO - C:\Users\ASWANI\new prj-Trouble Tracker\trouble_tracker\trouble_app\views.py changed, reloading.
2024-06-11 14:15:24,760 - ERROR - Internal Server Error: /create_issue/
Traceback (most recent call last):
  File "C:\Users\ASWANI\AppData\Local\Programs\Python\Python312\Lib\site-packages\django\db\backends\utils.py", line 105, in _execute
    return self.cursor.execute(sql, params)
           ^^^^^^^^^^^^^^^^^^^^^^^^^^^^^^^^
  File "C:\Users\ASWANI\AppData\Local\Programs\Python\Python312\Lib\site-packages\django\db\backends\mysql\base.py", line 75, in execute
    return self.cursor.execute(query, args)
           ^^^^^^^^^^^^^^^^^^^^^^^^^^^^^^^^
  File "C:\Users\ASWANI\AppData\Local\Programs\Python\Python312\Lib\site-packages\MySQLdb\cursors.py", line 179, in execute
    res = self._query(mogrified_query)
          ^^^^^^^^^^^^^^^^^^^^^^^^^^^^
  File "C:\Users\ASWANI\AppData\Local\Programs\Python\Python312\Lib\site-packages\MySQLdb\cursors.py", line 330, in _query
    db.query(q)
  File "C:\Users\ASWANI\AppData\Local\Programs\Python\Python312\Lib\site-packages\MySQLdb\connections.py", line 261, in query
    _mysql.connection.query(self, query)
MySQLdb.IntegrityError: (1062, "Duplicate entry 'issue_list.html-8' for key 'trouble_app_issue.trouble_app_issue_title_created_by_id_ce282d39_uniq'")

The above exception was the direct cause of the following exception:

Traceback (most recent call last):
  File "C:\Users\ASWANI\AppData\Local\Programs\Python\Python312\Lib\site-packages\django\core\handlers\exception.py", line 55, in inner
    response = get_response(request)
               ^^^^^^^^^^^^^^^^^^^^^
  File "C:\Users\ASWANI\AppData\Local\Programs\Python\Python312\Lib\site-packages\django\core\handlers\base.py", line 197, in _get_response
    response = wrapped_callback(request, *callback_args, **callback_kwargs)
               ^^^^^^^^^^^^^^^^^^^^^^^^^^^^^^^^^^^^^^^^^^^^^^^^^^^^^^^^^^^^
  File "C:\Users\ASWANI\AppData\Local\Programs\Python\Python312\Lib\site-packages\django\contrib\auth\decorators.py", line 23, in _wrapper_view
    return view_func(request, *args, **kwargs)
           ^^^^^^^^^^^^^^^^^^^^^^^^^^^^^^^^^^^
  File "C:\Users\ASWANI\new prj-Trouble Tracker\trouble_tracker\trouble_app\views.py", line 120, in create_issue
    new_issue.save()
  File "C:\Users\ASWANI\AppData\Local\Programs\Python\Python312\Lib\site-packages\django\db\models\base.py", line 822, in save
    self.save_base(
  File "C:\Users\ASWANI\AppData\Local\Programs\Python\Python312\Lib\site-packages\django\db\models\base.py", line 909, in save_base
    updated = self._save_table(
              ^^^^^^^^^^^^^^^^^
  File "C:\Users\ASWANI\AppData\Local\Programs\Python\Python312\Lib\site-packages\django\db\models\base.py", line 1067, in _save_table
    results = self._do_insert(
              ^^^^^^^^^^^^^^^^
  File "C:\Users\ASWANI\AppData\Local\Programs\Python\Python312\Lib\site-packages\django\db\models\base.py", line 1108, in _do_insert
    return manager._insert(
           ^^^^^^^^^^^^^^^^
  File "C:\Users\ASWANI\AppData\Local\Programs\Python\Python312\Lib\site-packages\django\db\models\manager.py", line 87, in manager_method
    return getattr(self.get_queryset(), name)(*args, **kwargs)
           ^^^^^^^^^^^^^^^^^^^^^^^^^^^^^^^^^^^^^^^^^^^^^^^^^^^
  File "C:\Users\ASWANI\AppData\Local\Programs\Python\Python312\Lib\site-packages\django\db\models\query.py", line 1845, in _insert
    return query.get_compiler(using=using).execute_sql(returning_fields)
           ^^^^^^^^^^^^^^^^^^^^^^^^^^^^^^^^^^^^^^^^^^^^^^^^^^^^^^^^^^^^^
  File "C:\Users\ASWANI\AppData\Local\Programs\Python\Python312\Lib\site-packages\django\db\models\sql\compiler.py", line 1823, in execute_sql
    cursor.execute(sql, params)
  File "C:\Users\ASWANI\AppData\Local\Programs\Python\Python312\Lib\site-packages\django\db\backends\utils.py", line 122, in execute
    return super().execute(sql, params)
           ^^^^^^^^^^^^^^^^^^^^^^^^^^^^
  File "C:\Users\ASWANI\AppData\Local\Programs\Python\Python312\Lib\site-packages\django\db\backends\utils.py", line 79, in execute
    return self._execute_with_wrappers(
           ^^^^^^^^^^^^^^^^^^^^^^^^^^^^
  File "C:\Users\ASWANI\AppData\Local\Programs\Python\Python312\Lib\site-packages\django\db\backends\utils.py", line 92, in _execute_with_wrappers
    return executor(sql, params, many, context)
           ^^^^^^^^^^^^^^^^^^^^^^^^^^^^^^^^^^^^
  File "C:\Users\ASWANI\AppData\Local\Programs\Python\Python312\Lib\site-packages\django\db\backends\utils.py", line 100, in _execute
    with self.db.wrap_database_errors:
  File "C:\Users\ASWANI\AppData\Local\Programs\Python\Python312\Lib\site-packages\django\db\utils.py", line 91, in __exit__
    raise dj_exc_value.with_traceback(traceback) from exc_value
  File "C:\Users\ASWANI\AppData\Local\Programs\Python\Python312\Lib\site-packages\django\db\backends\utils.py", line 105, in _execute
    return self.cursor.execute(sql, params)
           ^^^^^^^^^^^^^^^^^^^^^^^^^^^^^^^^
  File "C:\Users\ASWANI\AppData\Local\Programs\Python\Python312\Lib\site-packages\django\db\backends\mysql\base.py", line 75, in execute
    return self.cursor.execute(query, args)
           ^^^^^^^^^^^^^^^^^^^^^^^^^^^^^^^^
  File "C:\Users\ASWANI\AppData\Local\Programs\Python\Python312\Lib\site-packages\MySQLdb\cursors.py", line 179, in execute
    res = self._query(mogrified_query)
          ^^^^^^^^^^^^^^^^^^^^^^^^^^^^
  File "C:\Users\ASWANI\AppData\Local\Programs\Python\Python312\Lib\site-packages\MySQLdb\cursors.py", line 330, in _query
    db.query(q)
  File "C:\Users\ASWANI\AppData\Local\Programs\Python\Python312\Lib\site-packages\MySQLdb\connections.py", line 261, in query
    _mysql.connection.query(self, query)
django.db.utils.IntegrityError: (1062, "Duplicate entry 'issue_list.html-8' for key 'trouble_app_issue.trouble_app_issue_title_created_by_id_ce282d39_uniq'")
2024-06-11 14:16:30,171 - INFO - C:\Users\ASWANI\new prj-Trouble Tracker\trouble_tracker\trouble_app\views.py changed, reloading.
2024-06-11 14:16:32,408 - INFO - C:\Users\ASWANI\new prj-Trouble Tracker\trouble_tracker\trouble_app\views.py changed, reloading.
2024-06-11 14:30:46,462 - INFO - C:\Users\ASWANI\new prj-Trouble Tracker\trouble_tracker\trouble_app\views.py changed, reloading.
2024-06-27 16:10:55,711 - WARNING - Not Found: /favicon.ico
2024-06-27 16:15:17,171 - WARNING - Forbidden (CSRF token from POST incorrect.): /accounts/login/
2024-06-27 16:16:22,171 - WARNING - Not Found: /create_confirm_delete/
2024-06-27 16:27:23,247 - INFO - C:\Users\ASWANI\new prj-Trouble Tracker\trouble_tracker\trouble_tracker\urls.py changed, reloading.
2024-06-27 16:30:29,400 - INFO - C:\Users\ASWANI\new prj-Trouble Tracker\trouble_tracker\trouble_app\views.py changed, reloading.
2024-06-27 16:30:41,911 - INFO - C:\Users\ASWANI\new prj-Trouble Tracker\trouble_tracker\trouble_app\views.py changed, reloading.
2024-06-27 16:31:25,319 - INFO - C:\Users\ASWANI\new prj-Trouble Tracker\trouble_tracker\trouble_app\urls.py changed, reloading.
2024-06-27 16:31:42,222 - INFO - C:\Users\ASWANI\new prj-Trouble Tracker\trouble_tracker\trouble_app\views.py changed, reloading.
2024-06-27 16:32:02,468 - INFO - C:\Users\ASWANI\new prj-Trouble Tracker\trouble_tracker\trouble_app\views.py changed, reloading.
2024-06-27 16:32:11,144 - INFO - C:\Users\ASWANI\new prj-Trouble Tracker\trouble_tracker\trouble_app\views.py changed, reloading.
2024-06-27 16:32:28,408 - INFO - C:\Users\ASWANI\new prj-Trouble Tracker\trouble_tracker\trouble_app\urls.py changed, reloading.
2024-06-27 16:32:33,859 - INFO - C:\Users\ASWANI\new prj-Trouble Tracker\trouble_tracker\trouble_app\urls.py changed, reloading.
2024-06-27 16:43:47,301 - WARNING - Not Found: /issues/issue_confirm_delete/
2024-06-27 16:45:27,957 - INFO - C:\Users\ASWANI\new prj-Trouble Tracker\trouble_tracker\trouble_app\urls.py changed, reloading.
2024-06-27 16:45:35,715 - INFO - C:\Users\ASWANI\new prj-Trouble Tracker\trouble_tracker\trouble_app\urls.py changed, reloading.
2024-06-27 16:47:19,001 - INFO - C:\Users\ASWANI\new prj-Trouble Tracker\trouble_tracker\trouble_app\views.py changed, reloading.
2024-06-27 16:47:27,685 - INFO - C:\Users\ASWANI\new prj-Trouble Tracker\trouble_tracker\trouble_app\views.py changed, reloading.
2024-06-27 16:51:40,751 - WARNING - Not Found: /issues/create_confirm_delete/
2024-06-27 16:55:58,212 - INFO - C:\Users\ASWANI\new prj-Trouble Tracker\trouble_tracker\trouble_app\views.py changed, reloading.
2024-06-27 16:56:06,627 - INFO - C:\Users\ASWANI\new prj-Trouble Tracker\trouble_tracker\trouble_app\views.py changed, reloading.
2024-06-27 16:56:14,159 - INFO - C:\Users\ASWANI\new prj-Trouble Tracker\trouble_tracker\trouble_app\views.py changed, reloading.
2024-06-27 16:57:12,751 - INFO - C:\Users\ASWANI\new prj-Trouble Tracker\trouble_tracker\trouble_app\urls.py changed, reloading.
2024-06-27 16:57:27,635 - INFO - C:\Users\ASWANI\new prj-Trouble Tracker\trouble_tracker\trouble_app\urls.py changed, reloading.
2024-06-27 16:57:33,459 - INFO - C:\Users\ASWANI\new prj-Trouble Tracker\trouble_tracker\trouble_app\urls.py changed, reloading.
2024-06-27 16:58:56,071 - INFO - C:\Users\ASWANI\new prj-Trouble Tracker\trouble_tracker\trouble_app\urls.py changed, reloading.
2024-06-27 16:59:41,675 - WARNING - Not Found: /issues/create_confirm_delete/
2024-06-27 17:02:07,633 - ERROR - Internal Server Error: /create_confirm_delete/
Traceback (most recent call last):
  File "C:\Users\ASWANI\AppData\Local\Programs\Python\Python312\Lib\site-packages\django\core\handlers\exception.py", line 55, in inner
    response = get_response(request)
               ^^^^^^^^^^^^^^^^^^^^^
  File "C:\Users\ASWANI\AppData\Local\Programs\Python\Python312\Lib\site-packages\django\core\handlers\base.py", line 197, in _get_response
    response = wrapped_callback(request, *callback_args, **callback_kwargs)
               ^^^^^^^^^^^^^^^^^^^^^^^^^^^^^^^^^^^^^^^^^^^^^^^^^^^^^^^^^^^^
  File "C:\Users\ASWANI\AppData\Local\Programs\Python\Python312\Lib\site-packages\django\contrib\auth\decorators.py", line 23, in _wrapper_view
    return view_func(request, *args, **kwargs)
           ^^^^^^^^^^^^^^^^^^^^^^^^^^^^^^^^^^^
TypeError: create_confirm_delete() missing 1 required positional argument: 'issue_id'
2024-06-27 17:03:33,485 - INFO - C:\Users\ASWANI\new prj-Trouble Tracker\trouble_tracker\trouble_app\views.py changed, reloading.
2024-06-27 17:05:54,640 - ERROR - Internal Server Error: /create_confirm_delete/
Traceback (most recent call last):
  File "C:\Users\ASWANI\AppData\Local\Programs\Python\Python312\Lib\site-packages\django\core\handlers\exception.py", line 55, in inner
    response = get_response(request)
               ^^^^^^^^^^^^^^^^^^^^^
  File "C:\Users\ASWANI\AppData\Local\Programs\Python\Python312\Lib\site-packages\django\core\handlers\base.py", line 197, in _get_response
    response = wrapped_callback(request, *callback_args, **callback_kwargs)
               ^^^^^^^^^^^^^^^^^^^^^^^^^^^^^^^^^^^^^^^^^^^^^^^^^^^^^^^^^^^^
  File "C:\Users\ASWANI\AppData\Local\Programs\Python\Python312\Lib\site-packages\django\contrib\auth\decorators.py", line 23, in _wrapper_view
    return view_func(request, *args, **kwargs)
           ^^^^^^^^^^^^^^^^^^^^^^^^^^^^^^^^^^^
TypeError: create_confirm_delete() missing 1 required positional argument: 'issue_id'
2024-06-27 17:08:10,897 - INFO - C:\Users\ASWANI\new prj-Trouble Tracker\trouble_tracker\trouble_tracker\urls.py changed, reloading.
2024-06-27 17:08:13,313 - INFO - C:\Users\ASWANI\new prj-Trouble Tracker\trouble_tracker\trouble_tracker\urls.py changed, reloading.
2024-06-27 17:08:36,741 - WARNING - Not Found: /create_confirm_delete/
2024-06-27 17:11:04,604 - WARNING - Not Found: /create_confirm_delete/
2024-06-27 17:12:55,717 - INFO - C:\Users\ASWANI\new prj-Trouble Tracker\trouble_tracker\trouble_app\views.py changed, reloading.
2024-06-27 17:13:01,291 - INFO - C:\Users\ASWANI\new prj-Trouble Tracker\trouble_tracker\trouble_app\views.py changed, reloading.
2024-06-27 17:13:23,049 - WARNING - Not Found: /create_confirm_delete/
2024-06-27 17:15:40,741 - WARNING - Not Found: /issues/create_confirm_delete/
